[2024-12-16T17:46:24.334+0000] {processor.py:186} INFO - Started process (PID=3382) to work on /opt/airflow/dags/my_dag.py
[2024-12-16T17:46:24.336+0000] {processor.py:914} INFO - Processing file /opt/airflow/dags/my_dag.py for tasks to queue
[2024-12-16T17:46:24.338+0000] {logging_mixin.py:190} INFO - [2024-12-16T17:46:24.338+0000] {dagbag.py:588} INFO - Filling up the DagBag from /opt/airflow/dags/my_dag.py
[2024-12-16T17:46:24.366+0000] {logging_mixin.py:190} INFO - [2024-12-16T17:46:24.364+0000] {dagbag.py:387} ERROR - Failed to import: /opt/airflow/dags/my_dag.py
Traceback (most recent call last):
  File "/home/airflow/.local/lib/python3.12/site-packages/airflow/models/dagbag.py", line 383, in parse
    loader.exec_module(new_module)
  File "<frozen importlib._bootstrap_external>", line 995, in exec_module
  File "<frozen importlib._bootstrap_external>", line 1133, in get_code
  File "<frozen importlib._bootstrap_external>", line 1063, in source_to_code
  File "<frozen importlib._bootstrap>", line 488, in _call_with_frames_removed
  File "/opt/airflow/dags/my_dag.py", line 4
    with DAG("my_dag",start_date) as dag:
                                         ^
IndentationError: expected an indented block after 'with' statement on line 4
[2024-12-16T17:46:24.390+0000] {processor.py:927} WARNING - No viable dags retrieved from /opt/airflow/dags/my_dag.py
[2024-12-16T17:46:26.258+0000] {processor.py:208} INFO - Processing /opt/airflow/dags/my_dag.py took 1.935 seconds
[2024-12-16T17:46:57.198+0000] {processor.py:186} INFO - Started process (PID=3451) to work on /opt/airflow/dags/my_dag.py
[2024-12-16T17:46:57.200+0000] {processor.py:914} INFO - Processing file /opt/airflow/dags/my_dag.py for tasks to queue
[2024-12-16T17:46:57.203+0000] {logging_mixin.py:190} INFO - [2024-12-16T17:46:57.202+0000] {dagbag.py:588} INFO - Filling up the DagBag from /opt/airflow/dags/my_dag.py
[2024-12-16T17:46:57.223+0000] {logging_mixin.py:190} INFO - [2024-12-16T17:46:57.221+0000] {dagbag.py:387} ERROR - Failed to import: /opt/airflow/dags/my_dag.py
Traceback (most recent call last):
  File "/home/airflow/.local/lib/python3.12/site-packages/airflow/models/dagbag.py", line 383, in parse
    loader.exec_module(new_module)
  File "<frozen importlib._bootstrap_external>", line 995, in exec_module
  File "<frozen importlib._bootstrap_external>", line 1133, in get_code
  File "<frozen importlib._bootstrap_external>", line 1063, in source_to_code
  File "<frozen importlib._bootstrap>", line 488, in _call_with_frames_removed
  File "/opt/airflow/dags/my_dag.py", line 4
    with DAG("my_dag",start_date) as dag:
                                         ^
IndentationError: expected an indented block after 'with' statement on line 4
[2024-12-16T17:46:57.224+0000] {processor.py:927} WARNING - No viable dags retrieved from /opt/airflow/dags/my_dag.py
[2024-12-16T17:46:57.665+0000] {processor.py:208} INFO - Processing /opt/airflow/dags/my_dag.py took 0.478 seconds
[2024-12-16T17:47:28.583+0000] {processor.py:186} INFO - Started process (PID=3515) to work on /opt/airflow/dags/my_dag.py
[2024-12-16T17:47:28.585+0000] {processor.py:914} INFO - Processing file /opt/airflow/dags/my_dag.py for tasks to queue
[2024-12-16T17:47:28.588+0000] {logging_mixin.py:190} INFO - [2024-12-16T17:47:28.588+0000] {dagbag.py:588} INFO - Filling up the DagBag from /opt/airflow/dags/my_dag.py
[2024-12-16T17:47:28.608+0000] {logging_mixin.py:190} INFO - [2024-12-16T17:47:28.606+0000] {dagbag.py:387} ERROR - Failed to import: /opt/airflow/dags/my_dag.py
Traceback (most recent call last):
  File "/home/airflow/.local/lib/python3.12/site-packages/airflow/models/dagbag.py", line 383, in parse
    loader.exec_module(new_module)
  File "<frozen importlib._bootstrap_external>", line 995, in exec_module
  File "<frozen importlib._bootstrap_external>", line 1133, in get_code
  File "<frozen importlib._bootstrap_external>", line 1063, in source_to_code
  File "<frozen importlib._bootstrap>", line 488, in _call_with_frames_removed
  File "/opt/airflow/dags/my_dag.py", line 4
    with DAG("my_dag",start_date) as dag:
                                         ^
IndentationError: expected an indented block after 'with' statement on line 4
[2024-12-16T17:47:28.610+0000] {processor.py:927} WARNING - No viable dags retrieved from /opt/airflow/dags/my_dag.py
[2024-12-16T17:47:29.467+0000] {processor.py:208} INFO - Processing /opt/airflow/dags/my_dag.py took 0.896 seconds
[2024-12-16T17:47:59.665+0000] {processor.py:186} INFO - Started process (PID=3575) to work on /opt/airflow/dags/my_dag.py
[2024-12-16T17:47:59.667+0000] {processor.py:914} INFO - Processing file /opt/airflow/dags/my_dag.py for tasks to queue
[2024-12-16T17:47:59.671+0000] {logging_mixin.py:190} INFO - [2024-12-16T17:47:59.670+0000] {dagbag.py:588} INFO - Filling up the DagBag from /opt/airflow/dags/my_dag.py
[2024-12-16T17:47:59.699+0000] {logging_mixin.py:190} INFO - [2024-12-16T17:47:59.695+0000] {dagbag.py:387} ERROR - Failed to import: /opt/airflow/dags/my_dag.py
Traceback (most recent call last):
  File "/home/airflow/.local/lib/python3.12/site-packages/airflow/models/dagbag.py", line 383, in parse
    loader.exec_module(new_module)
  File "<frozen importlib._bootstrap_external>", line 995, in exec_module
  File "<frozen importlib._bootstrap_external>", line 1133, in get_code
  File "<frozen importlib._bootstrap_external>", line 1063, in source_to_code
  File "<frozen importlib._bootstrap>", line 488, in _call_with_frames_removed
  File "/opt/airflow/dags/my_dag.py", line 4
    with DAG("my_dag",start_date) as dag:
                                         ^
IndentationError: expected an indented block after 'with' statement on line 4
[2024-12-16T17:47:59.700+0000] {processor.py:927} WARNING - No viable dags retrieved from /opt/airflow/dags/my_dag.py
[2024-12-16T17:47:59.834+0000] {processor.py:208} INFO - Processing /opt/airflow/dags/my_dag.py took 0.184 seconds
[2024-12-16T17:48:31.906+0000] {processor.py:186} INFO - Started process (PID=3634) to work on /opt/airflow/dags/my_dag.py
[2024-12-16T17:48:31.908+0000] {processor.py:914} INFO - Processing file /opt/airflow/dags/my_dag.py for tasks to queue
[2024-12-16T17:48:31.911+0000] {logging_mixin.py:190} INFO - [2024-12-16T17:48:31.910+0000] {dagbag.py:588} INFO - Filling up the DagBag from /opt/airflow/dags/my_dag.py
[2024-12-16T17:48:31.932+0000] {logging_mixin.py:190} INFO - [2024-12-16T17:48:31.930+0000] {dagbag.py:387} ERROR - Failed to import: /opt/airflow/dags/my_dag.py
Traceback (most recent call last):
  File "/home/airflow/.local/lib/python3.12/site-packages/airflow/models/dagbag.py", line 383, in parse
    loader.exec_module(new_module)
  File "<frozen importlib._bootstrap_external>", line 995, in exec_module
  File "<frozen importlib._bootstrap_external>", line 1133, in get_code
  File "<frozen importlib._bootstrap_external>", line 1063, in source_to_code
  File "<frozen importlib._bootstrap>", line 488, in _call_with_frames_removed
  File "/opt/airflow/dags/my_dag.py", line 4
    with DAG("my_dag",start_date) as dag:
                                         ^
IndentationError: expected an indented block after 'with' statement on line 4
[2024-12-16T17:48:31.933+0000] {processor.py:927} WARNING - No viable dags retrieved from /opt/airflow/dags/my_dag.py
[2024-12-16T17:48:32.971+0000] {processor.py:208} INFO - Processing /opt/airflow/dags/my_dag.py took 1.076 seconds
[2024-12-16T17:49:03.571+0000] {processor.py:186} INFO - Started process (PID=3686) to work on /opt/airflow/dags/my_dag.py
[2024-12-16T17:49:03.574+0000] {processor.py:914} INFO - Processing file /opt/airflow/dags/my_dag.py for tasks to queue
[2024-12-16T17:49:03.577+0000] {logging_mixin.py:190} INFO - [2024-12-16T17:49:03.576+0000] {dagbag.py:588} INFO - Filling up the DagBag from /opt/airflow/dags/my_dag.py
[2024-12-16T17:49:03.604+0000] {logging_mixin.py:190} INFO - [2024-12-16T17:49:03.602+0000] {dagbag.py:387} ERROR - Failed to import: /opt/airflow/dags/my_dag.py
Traceback (most recent call last):
  File "/home/airflow/.local/lib/python3.12/site-packages/airflow/models/dagbag.py", line 383, in parse
    loader.exec_module(new_module)
  File "<frozen importlib._bootstrap_external>", line 995, in exec_module
  File "<frozen importlib._bootstrap_external>", line 1133, in get_code
  File "<frozen importlib._bootstrap_external>", line 1063, in source_to_code
  File "<frozen importlib._bootstrap>", line 488, in _call_with_frames_removed
  File "/opt/airflow/dags/my_dag.py", line 4
    with DAG("my_dag",start_date) as dag:
                                         ^
IndentationError: expected an indented block after 'with' statement on line 4
[2024-12-16T17:49:03.606+0000] {processor.py:927} WARNING - No viable dags retrieved from /opt/airflow/dags/my_dag.py
[2024-12-16T17:49:03.690+0000] {processor.py:208} INFO - Processing /opt/airflow/dags/my_dag.py took 0.136 seconds
[2024-12-16T17:49:35.206+0000] {processor.py:186} INFO - Started process (PID=3747) to work on /opt/airflow/dags/my_dag.py
[2024-12-16T17:49:35.207+0000] {processor.py:914} INFO - Processing file /opt/airflow/dags/my_dag.py for tasks to queue
[2024-12-16T17:49:35.211+0000] {logging_mixin.py:190} INFO - [2024-12-16T17:49:35.210+0000] {dagbag.py:588} INFO - Filling up the DagBag from /opt/airflow/dags/my_dag.py
[2024-12-16T17:49:35.241+0000] {logging_mixin.py:190} INFO - [2024-12-16T17:49:35.240+0000] {dagbag.py:387} ERROR - Failed to import: /opt/airflow/dags/my_dag.py
Traceback (most recent call last):
  File "/home/airflow/.local/lib/python3.12/site-packages/airflow/models/dagbag.py", line 383, in parse
    loader.exec_module(new_module)
  File "<frozen importlib._bootstrap_external>", line 995, in exec_module
  File "<frozen importlib._bootstrap_external>", line 1133, in get_code
  File "<frozen importlib._bootstrap_external>", line 1063, in source_to_code
  File "<frozen importlib._bootstrap>", line 488, in _call_with_frames_removed
  File "/opt/airflow/dags/my_dag.py", line 4
    with DAG("my_dag",start_date) as dag:
                                         ^
IndentationError: expected an indented block after 'with' statement on line 4
[2024-12-16T17:49:35.243+0000] {processor.py:927} WARNING - No viable dags retrieved from /opt/airflow/dags/my_dag.py
[2024-12-16T17:49:36.089+0000] {processor.py:208} INFO - Processing /opt/airflow/dags/my_dag.py took 0.895 seconds
[2024-12-16T17:50:06.653+0000] {processor.py:186} INFO - Started process (PID=3810) to work on /opt/airflow/dags/my_dag.py
[2024-12-16T17:50:06.655+0000] {processor.py:914} INFO - Processing file /opt/airflow/dags/my_dag.py for tasks to queue
[2024-12-16T17:50:06.659+0000] {logging_mixin.py:190} INFO - [2024-12-16T17:50:06.659+0000] {dagbag.py:588} INFO - Filling up the DagBag from /opt/airflow/dags/my_dag.py
[2024-12-16T17:50:06.685+0000] {logging_mixin.py:190} INFO - [2024-12-16T17:50:06.683+0000] {dagbag.py:387} ERROR - Failed to import: /opt/airflow/dags/my_dag.py
Traceback (most recent call last):
  File "/home/airflow/.local/lib/python3.12/site-packages/airflow/models/dagbag.py", line 383, in parse
    loader.exec_module(new_module)
  File "<frozen importlib._bootstrap_external>", line 995, in exec_module
  File "<frozen importlib._bootstrap_external>", line 1133, in get_code
  File "<frozen importlib._bootstrap_external>", line 1063, in source_to_code
  File "<frozen importlib._bootstrap>", line 488, in _call_with_frames_removed
  File "/opt/airflow/dags/my_dag.py", line 4
    with DAG("my_dag",start_date) as dag:
                                         ^
IndentationError: expected an indented block after 'with' statement on line 4
[2024-12-16T17:50:06.687+0000] {processor.py:927} WARNING - No viable dags retrieved from /opt/airflow/dags/my_dag.py
[2024-12-16T17:50:06.769+0000] {processor.py:208} INFO - Processing /opt/airflow/dags/my_dag.py took 0.135 seconds
[2024-12-16T17:50:36.912+0000] {processor.py:186} INFO - Started process (PID=3874) to work on /opt/airflow/dags/my_dag.py
[2024-12-16T17:50:36.914+0000] {processor.py:914} INFO - Processing file /opt/airflow/dags/my_dag.py for tasks to queue
[2024-12-16T17:50:36.918+0000] {logging_mixin.py:190} INFO - [2024-12-16T17:50:36.916+0000] {dagbag.py:588} INFO - Filling up the DagBag from /opt/airflow/dags/my_dag.py
[2024-12-16T17:50:36.945+0000] {logging_mixin.py:190} INFO - [2024-12-16T17:50:36.943+0000] {dagbag.py:387} ERROR - Failed to import: /opt/airflow/dags/my_dag.py
Traceback (most recent call last):
  File "/home/airflow/.local/lib/python3.12/site-packages/airflow/models/dagbag.py", line 383, in parse
    loader.exec_module(new_module)
  File "<frozen importlib._bootstrap_external>", line 995, in exec_module
  File "<frozen importlib._bootstrap_external>", line 1133, in get_code
  File "<frozen importlib._bootstrap_external>", line 1063, in source_to_code
  File "<frozen importlib._bootstrap>", line 488, in _call_with_frames_removed
  File "/opt/airflow/dags/my_dag.py", line 4
    with DAG("my_dag",start_date) as dag:
                                         ^
IndentationError: expected an indented block after 'with' statement on line 4
[2024-12-16T17:50:36.947+0000] {processor.py:927} WARNING - No viable dags retrieved from /opt/airflow/dags/my_dag.py
[2024-12-16T17:50:37.024+0000] {processor.py:208} INFO - Processing /opt/airflow/dags/my_dag.py took 0.127 seconds
[2024-12-16T17:51:07.598+0000] {processor.py:186} INFO - Started process (PID=3937) to work on /opt/airflow/dags/my_dag.py
[2024-12-16T17:51:07.600+0000] {processor.py:914} INFO - Processing file /opt/airflow/dags/my_dag.py for tasks to queue
[2024-12-16T17:51:07.603+0000] {logging_mixin.py:190} INFO - [2024-12-16T17:51:07.602+0000] {dagbag.py:588} INFO - Filling up the DagBag from /opt/airflow/dags/my_dag.py
[2024-12-16T17:51:07.627+0000] {logging_mixin.py:190} INFO - [2024-12-16T17:51:07.625+0000] {dagbag.py:387} ERROR - Failed to import: /opt/airflow/dags/my_dag.py
Traceback (most recent call last):
  File "/home/airflow/.local/lib/python3.12/site-packages/airflow/models/dagbag.py", line 383, in parse
    loader.exec_module(new_module)
  File "<frozen importlib._bootstrap_external>", line 995, in exec_module
  File "<frozen importlib._bootstrap_external>", line 1133, in get_code
  File "<frozen importlib._bootstrap_external>", line 1063, in source_to_code
  File "<frozen importlib._bootstrap>", line 488, in _call_with_frames_removed
  File "/opt/airflow/dags/my_dag.py", line 4
    with DAG("my_dag",start_date) as dag:
                                         ^
IndentationError: expected an indented block after 'with' statement on line 4
[2024-12-16T17:51:07.630+0000] {processor.py:927} WARNING - No viable dags retrieved from /opt/airflow/dags/my_dag.py
[2024-12-16T17:51:08.002+0000] {processor.py:208} INFO - Processing /opt/airflow/dags/my_dag.py took 0.425 seconds
[2024-12-16T17:51:38.354+0000] {processor.py:186} INFO - Started process (PID=4001) to work on /opt/airflow/dags/my_dag.py
[2024-12-16T17:51:38.357+0000] {processor.py:914} INFO - Processing file /opt/airflow/dags/my_dag.py for tasks to queue
[2024-12-16T17:51:38.361+0000] {logging_mixin.py:190} INFO - [2024-12-16T17:51:38.360+0000] {dagbag.py:588} INFO - Filling up the DagBag from /opt/airflow/dags/my_dag.py
[2024-12-16T17:51:38.398+0000] {logging_mixin.py:190} INFO - [2024-12-16T17:51:38.396+0000] {dagbag.py:387} ERROR - Failed to import: /opt/airflow/dags/my_dag.py
Traceback (most recent call last):
  File "/home/airflow/.local/lib/python3.12/site-packages/airflow/models/dagbag.py", line 383, in parse
    loader.exec_module(new_module)
  File "<frozen importlib._bootstrap_external>", line 995, in exec_module
  File "<frozen importlib._bootstrap_external>", line 1133, in get_code
  File "<frozen importlib._bootstrap_external>", line 1063, in source_to_code
  File "<frozen importlib._bootstrap>", line 488, in _call_with_frames_removed
  File "/opt/airflow/dags/my_dag.py", line 4
    with DAG("my_dag",start_date) as dag:
                                         ^
IndentationError: expected an indented block after 'with' statement on line 4
[2024-12-16T17:51:38.401+0000] {processor.py:927} WARNING - No viable dags retrieved from /opt/airflow/dags/my_dag.py
[2024-12-16T17:51:39.265+0000] {processor.py:208} INFO - Processing /opt/airflow/dags/my_dag.py took 0.930 seconds
[2024-12-16T17:52:09.679+0000] {processor.py:186} INFO - Started process (PID=4066) to work on /opt/airflow/dags/my_dag.py
[2024-12-16T17:52:09.681+0000] {processor.py:914} INFO - Processing file /opt/airflow/dags/my_dag.py for tasks to queue
[2024-12-16T17:52:09.685+0000] {logging_mixin.py:190} INFO - [2024-12-16T17:52:09.684+0000] {dagbag.py:588} INFO - Filling up the DagBag from /opt/airflow/dags/my_dag.py
[2024-12-16T17:52:09.718+0000] {logging_mixin.py:190} INFO - [2024-12-16T17:52:09.715+0000] {dagbag.py:387} ERROR - Failed to import: /opt/airflow/dags/my_dag.py
Traceback (most recent call last):
  File "/home/airflow/.local/lib/python3.12/site-packages/airflow/models/dagbag.py", line 383, in parse
    loader.exec_module(new_module)
  File "<frozen importlib._bootstrap_external>", line 995, in exec_module
  File "<frozen importlib._bootstrap_external>", line 1133, in get_code
  File "<frozen importlib._bootstrap_external>", line 1063, in source_to_code
  File "<frozen importlib._bootstrap>", line 488, in _call_with_frames_removed
  File "/opt/airflow/dags/my_dag.py", line 4
    with DAG("my_dag",start_date) as dag:
                                         ^
IndentationError: expected an indented block after 'with' statement on line 4
[2024-12-16T17:52:09.721+0000] {processor.py:927} WARNING - No viable dags retrieved from /opt/airflow/dags/my_dag.py
[2024-12-16T17:52:11.121+0000] {processor.py:208} INFO - Processing /opt/airflow/dags/my_dag.py took 1.472 seconds
[2024-12-16T17:52:42.136+0000] {processor.py:186} INFO - Started process (PID=4130) to work on /opt/airflow/dags/my_dag.py
[2024-12-16T17:52:42.138+0000] {processor.py:914} INFO - Processing file /opt/airflow/dags/my_dag.py for tasks to queue
[2024-12-16T17:52:42.141+0000] {logging_mixin.py:190} INFO - [2024-12-16T17:52:42.140+0000] {dagbag.py:588} INFO - Filling up the DagBag from /opt/airflow/dags/my_dag.py
[2024-12-16T17:52:43.545+0000] {logging_mixin.py:190} INFO - [2024-12-16T17:52:43.538+0000] {dagbag.py:387} ERROR - Failed to import: /opt/airflow/dags/my_dag.py
Traceback (most recent call last):
  File "/home/airflow/.local/lib/python3.12/site-packages/airflow/models/dagbag.py", line 383, in parse
    loader.exec_module(new_module)
  File "<frozen importlib._bootstrap_external>", line 995, in exec_module
  File "<frozen importlib._bootstrap_external>", line 1133, in get_code
  File "<frozen importlib._bootstrap_external>", line 1063, in source_to_code
  File "<frozen importlib._bootstrap>", line 488, in _call_with_frames_removed
  File "/opt/airflow/dags/my_dag.py", line 4
    with DAG("my_dag",start_date) as dag:
                                         ^
IndentationError: expected an indented block after 'with' statement on line 4
[2024-12-16T17:52:43.549+0000] {processor.py:927} WARNING - No viable dags retrieved from /opt/airflow/dags/my_dag.py
[2024-12-16T17:52:43.727+0000] {processor.py:208} INFO - Processing /opt/airflow/dags/my_dag.py took 1.608 seconds
[2024-12-16T17:53:14.053+0000] {processor.py:186} INFO - Started process (PID=4194) to work on /opt/airflow/dags/my_dag.py
[2024-12-16T17:53:14.065+0000] {processor.py:914} INFO - Processing file /opt/airflow/dags/my_dag.py for tasks to queue
[2024-12-16T17:53:14.080+0000] {logging_mixin.py:190} INFO - [2024-12-16T17:53:14.069+0000] {dagbag.py:588} INFO - Filling up the DagBag from /opt/airflow/dags/my_dag.py
[2024-12-16T17:53:14.118+0000] {logging_mixin.py:190} INFO - [2024-12-16T17:53:14.116+0000] {dagbag.py:387} ERROR - Failed to import: /opt/airflow/dags/my_dag.py
Traceback (most recent call last):
  File "/home/airflow/.local/lib/python3.12/site-packages/airflow/models/dagbag.py", line 383, in parse
    loader.exec_module(new_module)
  File "<frozen importlib._bootstrap_external>", line 995, in exec_module
  File "<frozen importlib._bootstrap_external>", line 1133, in get_code
  File "<frozen importlib._bootstrap_external>", line 1063, in source_to_code
  File "<frozen importlib._bootstrap>", line 488, in _call_with_frames_removed
  File "/opt/airflow/dags/my_dag.py", line 4
    with DAG("my_dag",start_date) as dag:
                                         ^
IndentationError: expected an indented block after 'with' statement on line 4
[2024-12-16T17:53:14.124+0000] {processor.py:927} WARNING - No viable dags retrieved from /opt/airflow/dags/my_dag.py
[2024-12-16T17:53:14.262+0000] {processor.py:208} INFO - Processing /opt/airflow/dags/my_dag.py took 0.248 seconds
[2024-12-16T17:53:44.839+0000] {processor.py:186} INFO - Started process (PID=4258) to work on /opt/airflow/dags/my_dag.py
[2024-12-16T17:53:44.841+0000] {processor.py:914} INFO - Processing file /opt/airflow/dags/my_dag.py for tasks to queue
[2024-12-16T17:53:44.844+0000] {logging_mixin.py:190} INFO - [2024-12-16T17:53:44.843+0000] {dagbag.py:588} INFO - Filling up the DagBag from /opt/airflow/dags/my_dag.py
[2024-12-16T17:53:44.875+0000] {logging_mixin.py:190} INFO - [2024-12-16T17:53:44.874+0000] {dagbag.py:387} ERROR - Failed to import: /opt/airflow/dags/my_dag.py
Traceback (most recent call last):
  File "/home/airflow/.local/lib/python3.12/site-packages/airflow/models/dagbag.py", line 383, in parse
    loader.exec_module(new_module)
  File "<frozen importlib._bootstrap_external>", line 995, in exec_module
  File "<frozen importlib._bootstrap_external>", line 1133, in get_code
  File "<frozen importlib._bootstrap_external>", line 1063, in source_to_code
  File "<frozen importlib._bootstrap>", line 488, in _call_with_frames_removed
  File "/opt/airflow/dags/my_dag.py", line 4
    with DAG("my_dag",start_date) as dag:
                                         ^
IndentationError: expected an indented block after 'with' statement on line 4
[2024-12-16T17:53:44.877+0000] {processor.py:927} WARNING - No viable dags retrieved from /opt/airflow/dags/my_dag.py
[2024-12-16T17:53:45.309+0000] {processor.py:208} INFO - Processing /opt/airflow/dags/my_dag.py took 0.481 seconds
[2024-12-16T17:54:15.763+0000] {processor.py:186} INFO - Started process (PID=4321) to work on /opt/airflow/dags/my_dag.py
[2024-12-16T17:54:15.765+0000] {processor.py:914} INFO - Processing file /opt/airflow/dags/my_dag.py for tasks to queue
[2024-12-16T17:54:15.769+0000] {logging_mixin.py:190} INFO - [2024-12-16T17:54:15.768+0000] {dagbag.py:588} INFO - Filling up the DagBag from /opt/airflow/dags/my_dag.py
[2024-12-16T17:54:15.795+0000] {logging_mixin.py:190} INFO - [2024-12-16T17:54:15.792+0000] {dagbag.py:387} ERROR - Failed to import: /opt/airflow/dags/my_dag.py
Traceback (most recent call last):
  File "/home/airflow/.local/lib/python3.12/site-packages/airflow/models/dagbag.py", line 383, in parse
    loader.exec_module(new_module)
  File "<frozen importlib._bootstrap_external>", line 995, in exec_module
  File "<frozen importlib._bootstrap_external>", line 1133, in get_code
  File "<frozen importlib._bootstrap_external>", line 1063, in source_to_code
  File "<frozen importlib._bootstrap>", line 488, in _call_with_frames_removed
  File "/opt/airflow/dags/my_dag.py", line 4
    with DAG("my_dag",start_date) as dag:
                                         ^
IndentationError: expected an indented block after 'with' statement on line 4
[2024-12-16T17:54:15.798+0000] {processor.py:927} WARNING - No viable dags retrieved from /opt/airflow/dags/my_dag.py
[2024-12-16T17:54:17.288+0000] {processor.py:208} INFO - Processing /opt/airflow/dags/my_dag.py took 1.546 seconds
[2024-12-16T17:54:47.533+0000] {processor.py:186} INFO - Started process (PID=4384) to work on /opt/airflow/dags/my_dag.py
[2024-12-16T17:54:47.535+0000] {processor.py:914} INFO - Processing file /opt/airflow/dags/my_dag.py for tasks to queue
[2024-12-16T17:54:47.538+0000] {logging_mixin.py:190} INFO - [2024-12-16T17:54:47.537+0000] {dagbag.py:588} INFO - Filling up the DagBag from /opt/airflow/dags/my_dag.py
[2024-12-16T17:54:47.562+0000] {logging_mixin.py:190} INFO - [2024-12-16T17:54:47.559+0000] {dagbag.py:387} ERROR - Failed to import: /opt/airflow/dags/my_dag.py
Traceback (most recent call last):
  File "/home/airflow/.local/lib/python3.12/site-packages/airflow/models/dagbag.py", line 383, in parse
    loader.exec_module(new_module)
  File "<frozen importlib._bootstrap_external>", line 995, in exec_module
  File "<frozen importlib._bootstrap_external>", line 1133, in get_code
  File "<frozen importlib._bootstrap_external>", line 1063, in source_to_code
  File "<frozen importlib._bootstrap>", line 488, in _call_with_frames_removed
  File "/opt/airflow/dags/my_dag.py", line 4
    with DAG("my_dag",start_date) as dag:
                                         ^
IndentationError: expected an indented block after 'with' statement on line 4
[2024-12-16T17:54:47.564+0000] {processor.py:927} WARNING - No viable dags retrieved from /opt/airflow/dags/my_dag.py
[2024-12-16T17:54:47.933+0000] {processor.py:208} INFO - Processing /opt/airflow/dags/my_dag.py took 0.418 seconds
[2024-12-16T17:55:18.076+0000] {processor.py:186} INFO - Started process (PID=4447) to work on /opt/airflow/dags/my_dag.py
[2024-12-16T17:55:18.080+0000] {processor.py:914} INFO - Processing file /opt/airflow/dags/my_dag.py for tasks to queue
[2024-12-16T17:55:18.084+0000] {logging_mixin.py:190} INFO - [2024-12-16T17:55:18.083+0000] {dagbag.py:588} INFO - Filling up the DagBag from /opt/airflow/dags/my_dag.py
[2024-12-16T17:55:18.119+0000] {logging_mixin.py:190} INFO - [2024-12-16T17:55:18.117+0000] {dagbag.py:387} ERROR - Failed to import: /opt/airflow/dags/my_dag.py
Traceback (most recent call last):
  File "/home/airflow/.local/lib/python3.12/site-packages/airflow/models/dagbag.py", line 383, in parse
    loader.exec_module(new_module)
  File "<frozen importlib._bootstrap_external>", line 995, in exec_module
  File "<frozen importlib._bootstrap_external>", line 1133, in get_code
  File "<frozen importlib._bootstrap_external>", line 1063, in source_to_code
  File "<frozen importlib._bootstrap>", line 488, in _call_with_frames_removed
  File "/opt/airflow/dags/my_dag.py", line 4
    with DAG("my_dag",start_date) as dag:
                                         ^
IndentationError: expected an indented block after 'with' statement on line 4
[2024-12-16T17:55:18.121+0000] {processor.py:927} WARNING - No viable dags retrieved from /opt/airflow/dags/my_dag.py
[2024-12-16T17:55:18.210+0000] {processor.py:208} INFO - Processing /opt/airflow/dags/my_dag.py took 0.150 seconds
[2024-12-16T17:55:48.538+0000] {processor.py:186} INFO - Started process (PID=4511) to work on /opt/airflow/dags/my_dag.py
[2024-12-16T17:55:48.540+0000] {processor.py:914} INFO - Processing file /opt/airflow/dags/my_dag.py for tasks to queue
[2024-12-16T17:55:48.543+0000] {logging_mixin.py:190} INFO - [2024-12-16T17:55:48.542+0000] {dagbag.py:588} INFO - Filling up the DagBag from /opt/airflow/dags/my_dag.py
[2024-12-16T17:55:48.564+0000] {logging_mixin.py:190} INFO - [2024-12-16T17:55:48.562+0000] {dagbag.py:387} ERROR - Failed to import: /opt/airflow/dags/my_dag.py
Traceback (most recent call last):
  File "/home/airflow/.local/lib/python3.12/site-packages/airflow/models/dagbag.py", line 383, in parse
    loader.exec_module(new_module)
  File "<frozen importlib._bootstrap_external>", line 995, in exec_module
  File "<frozen importlib._bootstrap_external>", line 1133, in get_code
  File "<frozen importlib._bootstrap_external>", line 1063, in source_to_code
  File "<frozen importlib._bootstrap>", line 488, in _call_with_frames_removed
  File "/opt/airflow/dags/my_dag.py", line 4
    with DAG("my_dag",start_date) as dag:
                                         ^
IndentationError: expected an indented block after 'with' statement on line 4
[2024-12-16T17:55:48.565+0000] {processor.py:927} WARNING - No viable dags retrieved from /opt/airflow/dags/my_dag.py
[2024-12-16T17:55:48.633+0000] {processor.py:208} INFO - Processing /opt/airflow/dags/my_dag.py took 0.108 seconds
[2024-12-16T17:56:19.158+0000] {processor.py:186} INFO - Started process (PID=4572) to work on /opt/airflow/dags/my_dag.py
[2024-12-16T17:56:19.160+0000] {processor.py:914} INFO - Processing file /opt/airflow/dags/my_dag.py for tasks to queue
[2024-12-16T17:56:19.164+0000] {logging_mixin.py:190} INFO - [2024-12-16T17:56:19.163+0000] {dagbag.py:588} INFO - Filling up the DagBag from /opt/airflow/dags/my_dag.py
[2024-12-16T17:56:19.202+0000] {logging_mixin.py:190} INFO - [2024-12-16T17:56:19.199+0000] {dagbag.py:387} ERROR - Failed to import: /opt/airflow/dags/my_dag.py
Traceback (most recent call last):
  File "/home/airflow/.local/lib/python3.12/site-packages/airflow/models/dagbag.py", line 383, in parse
    loader.exec_module(new_module)
  File "<frozen importlib._bootstrap_external>", line 995, in exec_module
  File "<frozen importlib._bootstrap_external>", line 1133, in get_code
  File "<frozen importlib._bootstrap_external>", line 1063, in source_to_code
  File "<frozen importlib._bootstrap>", line 488, in _call_with_frames_removed
  File "/opt/airflow/dags/my_dag.py", line 4
    with DAG("my_dag",start_date) as dag:
                                         ^
IndentationError: expected an indented block after 'with' statement on line 4
[2024-12-16T17:56:19.211+0000] {processor.py:927} WARNING - No viable dags retrieved from /opt/airflow/dags/my_dag.py
[2024-12-16T17:56:19.322+0000] {processor.py:208} INFO - Processing /opt/airflow/dags/my_dag.py took 0.179 seconds
[2024-12-16T17:56:49.670+0000] {processor.py:186} INFO - Started process (PID=4631) to work on /opt/airflow/dags/my_dag.py
[2024-12-16T17:56:49.672+0000] {processor.py:914} INFO - Processing file /opt/airflow/dags/my_dag.py for tasks to queue
[2024-12-16T17:56:49.674+0000] {logging_mixin.py:190} INFO - [2024-12-16T17:56:49.673+0000] {dagbag.py:588} INFO - Filling up the DagBag from /opt/airflow/dags/my_dag.py
[2024-12-16T17:56:49.697+0000] {logging_mixin.py:190} INFO - [2024-12-16T17:56:49.695+0000] {dagbag.py:387} ERROR - Failed to import: /opt/airflow/dags/my_dag.py
Traceback (most recent call last):
  File "/home/airflow/.local/lib/python3.12/site-packages/airflow/models/dagbag.py", line 383, in parse
    loader.exec_module(new_module)
  File "<frozen importlib._bootstrap_external>", line 995, in exec_module
  File "<frozen importlib._bootstrap_external>", line 1133, in get_code
  File "<frozen importlib._bootstrap_external>", line 1063, in source_to_code
  File "<frozen importlib._bootstrap>", line 488, in _call_with_frames_removed
  File "/opt/airflow/dags/my_dag.py", line 4
    with DAG("my_dag",start_date) as dag:
                                         ^
IndentationError: expected an indented block after 'with' statement on line 4
[2024-12-16T17:56:49.698+0000] {processor.py:927} WARNING - No viable dags retrieved from /opt/airflow/dags/my_dag.py
[2024-12-16T17:56:49.771+0000] {processor.py:208} INFO - Processing /opt/airflow/dags/my_dag.py took 0.117 seconds
[2024-12-16T17:57:20.376+0000] {processor.py:186} INFO - Started process (PID=4694) to work on /opt/airflow/dags/my_dag.py
[2024-12-16T17:57:20.377+0000] {processor.py:914} INFO - Processing file /opt/airflow/dags/my_dag.py for tasks to queue
[2024-12-16T17:57:20.379+0000] {logging_mixin.py:190} INFO - [2024-12-16T17:57:20.379+0000] {dagbag.py:588} INFO - Filling up the DagBag from /opt/airflow/dags/my_dag.py
[2024-12-16T17:57:20.399+0000] {logging_mixin.py:190} INFO - [2024-12-16T17:57:20.396+0000] {dagbag.py:387} ERROR - Failed to import: /opt/airflow/dags/my_dag.py
Traceback (most recent call last):
  File "/home/airflow/.local/lib/python3.12/site-packages/airflow/models/dagbag.py", line 383, in parse
    loader.exec_module(new_module)
  File "<frozen importlib._bootstrap_external>", line 995, in exec_module
  File "<frozen importlib._bootstrap_external>", line 1133, in get_code
  File "<frozen importlib._bootstrap_external>", line 1063, in source_to_code
  File "<frozen importlib._bootstrap>", line 488, in _call_with_frames_removed
  File "/opt/airflow/dags/my_dag.py", line 4
    with DAG("my_dag",start_date) as dag:
                                         ^
IndentationError: expected an indented block after 'with' statement on line 4
[2024-12-16T17:57:20.401+0000] {processor.py:927} WARNING - No viable dags retrieved from /opt/airflow/dags/my_dag.py
[2024-12-16T17:57:20.492+0000] {processor.py:208} INFO - Processing /opt/airflow/dags/my_dag.py took 0.130 seconds
[2024-12-16T17:57:51.107+0000] {processor.py:186} INFO - Started process (PID=4757) to work on /opt/airflow/dags/my_dag.py
[2024-12-16T17:57:51.110+0000] {processor.py:914} INFO - Processing file /opt/airflow/dags/my_dag.py for tasks to queue
[2024-12-16T17:57:51.124+0000] {logging_mixin.py:190} INFO - [2024-12-16T17:57:51.118+0000] {dagbag.py:588} INFO - Filling up the DagBag from /opt/airflow/dags/my_dag.py
[2024-12-16T17:57:51.161+0000] {logging_mixin.py:190} INFO - [2024-12-16T17:57:51.159+0000] {dagbag.py:387} ERROR - Failed to import: /opt/airflow/dags/my_dag.py
Traceback (most recent call last):
  File "/home/airflow/.local/lib/python3.12/site-packages/airflow/models/dagbag.py", line 383, in parse
    loader.exec_module(new_module)
  File "<frozen importlib._bootstrap_external>", line 995, in exec_module
  File "<frozen importlib._bootstrap_external>", line 1133, in get_code
  File "<frozen importlib._bootstrap_external>", line 1063, in source_to_code
  File "<frozen importlib._bootstrap>", line 488, in _call_with_frames_removed
  File "/opt/airflow/dags/my_dag.py", line 4
    with DAG("my_dag",start_date) as dag:
                                         ^
IndentationError: expected an indented block after 'with' statement on line 4
[2024-12-16T17:57:51.163+0000] {processor.py:927} WARNING - No viable dags retrieved from /opt/airflow/dags/my_dag.py
[2024-12-16T17:57:51.549+0000] {processor.py:208} INFO - Processing /opt/airflow/dags/my_dag.py took 0.458 seconds
[2024-12-16T17:58:22.061+0000] {processor.py:186} INFO - Started process (PID=4821) to work on /opt/airflow/dags/my_dag.py
[2024-12-16T17:58:22.064+0000] {processor.py:914} INFO - Processing file /opt/airflow/dags/my_dag.py for tasks to queue
[2024-12-16T17:58:22.067+0000] {logging_mixin.py:190} INFO - [2024-12-16T17:58:22.066+0000] {dagbag.py:588} INFO - Filling up the DagBag from /opt/airflow/dags/my_dag.py
[2024-12-16T17:58:22.090+0000] {logging_mixin.py:190} INFO - [2024-12-16T17:58:22.087+0000] {dagbag.py:387} ERROR - Failed to import: /opt/airflow/dags/my_dag.py
Traceback (most recent call last):
  File "/home/airflow/.local/lib/python3.12/site-packages/airflow/models/dagbag.py", line 383, in parse
    loader.exec_module(new_module)
  File "<frozen importlib._bootstrap_external>", line 995, in exec_module
  File "<frozen importlib._bootstrap_external>", line 1133, in get_code
  File "<frozen importlib._bootstrap_external>", line 1063, in source_to_code
  File "<frozen importlib._bootstrap>", line 488, in _call_with_frames_removed
  File "/opt/airflow/dags/my_dag.py", line 4
    with DAG("my_dag",start_date) as dag:
                                         ^
IndentationError: expected an indented block after 'with' statement on line 4
[2024-12-16T17:58:22.092+0000] {processor.py:927} WARNING - No viable dags retrieved from /opt/airflow/dags/my_dag.py
[2024-12-16T17:58:22.774+0000] {processor.py:208} INFO - Processing /opt/airflow/dags/my_dag.py took 0.732 seconds
[2024-12-16T17:58:53.037+0000] {processor.py:186} INFO - Started process (PID=4885) to work on /opt/airflow/dags/my_dag.py
[2024-12-16T17:58:53.039+0000] {processor.py:914} INFO - Processing file /opt/airflow/dags/my_dag.py for tasks to queue
[2024-12-16T17:58:53.042+0000] {logging_mixin.py:190} INFO - [2024-12-16T17:58:53.041+0000] {dagbag.py:588} INFO - Filling up the DagBag from /opt/airflow/dags/my_dag.py
[2024-12-16T17:58:53.069+0000] {logging_mixin.py:190} INFO - [2024-12-16T17:58:53.066+0000] {dagbag.py:387} ERROR - Failed to import: /opt/airflow/dags/my_dag.py
Traceback (most recent call last):
  File "/home/airflow/.local/lib/python3.12/site-packages/airflow/models/dagbag.py", line 383, in parse
    loader.exec_module(new_module)
  File "<frozen importlib._bootstrap_external>", line 995, in exec_module
  File "<frozen importlib._bootstrap_external>", line 1133, in get_code
  File "<frozen importlib._bootstrap_external>", line 1063, in source_to_code
  File "<frozen importlib._bootstrap>", line 488, in _call_with_frames_removed
  File "/opt/airflow/dags/my_dag.py", line 4
    with DAG("my_dag",start_date) as dag:
                                         ^
IndentationError: expected an indented block after 'with' statement on line 4
[2024-12-16T17:58:53.070+0000] {processor.py:927} WARNING - No viable dags retrieved from /opt/airflow/dags/my_dag.py
[2024-12-16T17:58:54.233+0000] {processor.py:208} INFO - Processing /opt/airflow/dags/my_dag.py took 1.209 seconds
[2024-12-16T17:59:24.366+0000] {processor.py:186} INFO - Started process (PID=4949) to work on /opt/airflow/dags/my_dag.py
[2024-12-16T17:59:24.368+0000] {processor.py:914} INFO - Processing file /opt/airflow/dags/my_dag.py for tasks to queue
[2024-12-16T17:59:24.371+0000] {logging_mixin.py:190} INFO - [2024-12-16T17:59:24.371+0000] {dagbag.py:588} INFO - Filling up the DagBag from /opt/airflow/dags/my_dag.py
[2024-12-16T17:59:24.397+0000] {logging_mixin.py:190} INFO - [2024-12-16T17:59:24.394+0000] {dagbag.py:387} ERROR - Failed to import: /opt/airflow/dags/my_dag.py
Traceback (most recent call last):
  File "/home/airflow/.local/lib/python3.12/site-packages/airflow/models/dagbag.py", line 383, in parse
    loader.exec_module(new_module)
  File "<frozen importlib._bootstrap_external>", line 995, in exec_module
  File "<frozen importlib._bootstrap_external>", line 1133, in get_code
  File "<frozen importlib._bootstrap_external>", line 1063, in source_to_code
  File "<frozen importlib._bootstrap>", line 488, in _call_with_frames_removed
  File "/opt/airflow/dags/my_dag.py", line 4
    with DAG("my_dag",start_date) as dag:
                                         ^
IndentationError: expected an indented block after 'with' statement on line 4
[2024-12-16T17:59:24.399+0000] {processor.py:927} WARNING - No viable dags retrieved from /opt/airflow/dags/my_dag.py
[2024-12-16T17:59:24.502+0000] {processor.py:208} INFO - Processing /opt/airflow/dags/my_dag.py took 0.150 seconds
[2024-12-16T17:59:55.886+0000] {processor.py:186} INFO - Started process (PID=5013) to work on /opt/airflow/dags/my_dag.py
[2024-12-16T17:59:55.888+0000] {processor.py:914} INFO - Processing file /opt/airflow/dags/my_dag.py for tasks to queue
[2024-12-16T17:59:55.891+0000] {logging_mixin.py:190} INFO - [2024-12-16T17:59:55.890+0000] {dagbag.py:588} INFO - Filling up the DagBag from /opt/airflow/dags/my_dag.py
[2024-12-16T17:59:55.922+0000] {logging_mixin.py:190} INFO - [2024-12-16T17:59:55.920+0000] {dagbag.py:387} ERROR - Failed to import: /opt/airflow/dags/my_dag.py
Traceback (most recent call last):
  File "/home/airflow/.local/lib/python3.12/site-packages/airflow/models/dagbag.py", line 383, in parse
    loader.exec_module(new_module)
  File "<frozen importlib._bootstrap_external>", line 995, in exec_module
  File "<frozen importlib._bootstrap_external>", line 1133, in get_code
  File "<frozen importlib._bootstrap_external>", line 1063, in source_to_code
  File "<frozen importlib._bootstrap>", line 488, in _call_with_frames_removed
  File "/opt/airflow/dags/my_dag.py", line 4
    with DAG("my_dag",start_date) as dag:
                                         ^
IndentationError: expected an indented block after 'with' statement on line 4
[2024-12-16T17:59:55.924+0000] {processor.py:927} WARNING - No viable dags retrieved from /opt/airflow/dags/my_dag.py
[2024-12-16T17:59:55.991+0000] {processor.py:208} INFO - Processing /opt/airflow/dags/my_dag.py took 0.116 seconds
[2024-12-16T18:00:26.294+0000] {processor.py:186} INFO - Started process (PID=5075) to work on /opt/airflow/dags/my_dag.py
[2024-12-16T18:00:26.296+0000] {processor.py:914} INFO - Processing file /opt/airflow/dags/my_dag.py for tasks to queue
[2024-12-16T18:00:26.299+0000] {logging_mixin.py:190} INFO - [2024-12-16T18:00:26.298+0000] {dagbag.py:588} INFO - Filling up the DagBag from /opt/airflow/dags/my_dag.py
[2024-12-16T18:00:26.321+0000] {logging_mixin.py:190} INFO - [2024-12-16T18:00:26.319+0000] {dagbag.py:387} ERROR - Failed to import: /opt/airflow/dags/my_dag.py
Traceback (most recent call last):
  File "/home/airflow/.local/lib/python3.12/site-packages/airflow/models/dagbag.py", line 383, in parse
    loader.exec_module(new_module)
  File "<frozen importlib._bootstrap_external>", line 995, in exec_module
  File "<frozen importlib._bootstrap_external>", line 1133, in get_code
  File "<frozen importlib._bootstrap_external>", line 1063, in source_to_code
  File "<frozen importlib._bootstrap>", line 488, in _call_with_frames_removed
  File "/opt/airflow/dags/my_dag.py", line 4
    with DAG("my_dag",start_date) as dag:
                                         ^
IndentationError: expected an indented block after 'with' statement on line 4
[2024-12-16T18:00:26.323+0000] {processor.py:927} WARNING - No viable dags retrieved from /opt/airflow/dags/my_dag.py
[2024-12-16T18:00:26.400+0000] {processor.py:208} INFO - Processing /opt/airflow/dags/my_dag.py took 0.121 seconds
[2024-12-16T18:00:56.972+0000] {processor.py:186} INFO - Started process (PID=5138) to work on /opt/airflow/dags/my_dag.py
[2024-12-16T18:00:56.974+0000] {processor.py:914} INFO - Processing file /opt/airflow/dags/my_dag.py for tasks to queue
[2024-12-16T18:00:56.977+0000] {logging_mixin.py:190} INFO - [2024-12-16T18:00:56.976+0000] {dagbag.py:588} INFO - Filling up the DagBag from /opt/airflow/dags/my_dag.py
[2024-12-16T18:00:57.002+0000] {logging_mixin.py:190} INFO - [2024-12-16T18:00:56.999+0000] {dagbag.py:387} ERROR - Failed to import: /opt/airflow/dags/my_dag.py
Traceback (most recent call last):
  File "/home/airflow/.local/lib/python3.12/site-packages/airflow/models/dagbag.py", line 383, in parse
    loader.exec_module(new_module)
  File "<frozen importlib._bootstrap_external>", line 995, in exec_module
  File "<frozen importlib._bootstrap_external>", line 1133, in get_code
  File "<frozen importlib._bootstrap_external>", line 1063, in source_to_code
  File "<frozen importlib._bootstrap>", line 488, in _call_with_frames_removed
  File "/opt/airflow/dags/my_dag.py", line 4
    with DAG("my_dag",start_date) as dag:
                                         ^
IndentationError: expected an indented block after 'with' statement on line 4
[2024-12-16T18:00:57.003+0000] {processor.py:927} WARNING - No viable dags retrieved from /opt/airflow/dags/my_dag.py
[2024-12-16T18:00:57.262+0000] {processor.py:208} INFO - Processing /opt/airflow/dags/my_dag.py took 0.309 seconds
[2024-12-16T18:01:27.941+0000] {processor.py:186} INFO - Started process (PID=5203) to work on /opt/airflow/dags/my_dag.py
[2024-12-16T18:01:27.943+0000] {processor.py:914} INFO - Processing file /opt/airflow/dags/my_dag.py for tasks to queue
[2024-12-16T18:01:27.945+0000] {logging_mixin.py:190} INFO - [2024-12-16T18:01:27.944+0000] {dagbag.py:588} INFO - Filling up the DagBag from /opt/airflow/dags/my_dag.py
[2024-12-16T18:01:27.968+0000] {logging_mixin.py:190} INFO - [2024-12-16T18:01:27.967+0000] {dagbag.py:387} ERROR - Failed to import: /opt/airflow/dags/my_dag.py
Traceback (most recent call last):
  File "/home/airflow/.local/lib/python3.12/site-packages/airflow/models/dagbag.py", line 383, in parse
    loader.exec_module(new_module)
  File "<frozen importlib._bootstrap_external>", line 995, in exec_module
  File "<frozen importlib._bootstrap_external>", line 1133, in get_code
  File "<frozen importlib._bootstrap_external>", line 1063, in source_to_code
  File "<frozen importlib._bootstrap>", line 488, in _call_with_frames_removed
  File "/opt/airflow/dags/my_dag.py", line 4
    with DAG("my_dag",start_date) as dag:
                                         ^
IndentationError: expected an indented block after 'with' statement on line 4
[2024-12-16T18:01:27.970+0000] {processor.py:927} WARNING - No viable dags retrieved from /opt/airflow/dags/my_dag.py
[2024-12-16T18:01:28.449+0000] {processor.py:208} INFO - Processing /opt/airflow/dags/my_dag.py took 0.521 seconds
[2024-12-16T18:01:59.138+0000] {processor.py:186} INFO - Started process (PID=5267) to work on /opt/airflow/dags/my_dag.py
[2024-12-16T18:01:59.142+0000] {processor.py:914} INFO - Processing file /opt/airflow/dags/my_dag.py for tasks to queue
[2024-12-16T18:01:59.152+0000] {logging_mixin.py:190} INFO - [2024-12-16T18:01:59.151+0000] {dagbag.py:588} INFO - Filling up the DagBag from /opt/airflow/dags/my_dag.py
[2024-12-16T18:01:59.204+0000] {logging_mixin.py:190} INFO - [2024-12-16T18:01:59.201+0000] {dagbag.py:387} ERROR - Failed to import: /opt/airflow/dags/my_dag.py
Traceback (most recent call last):
  File "/home/airflow/.local/lib/python3.12/site-packages/airflow/models/dagbag.py", line 383, in parse
    loader.exec_module(new_module)
  File "<frozen importlib._bootstrap_external>", line 995, in exec_module
  File "<frozen importlib._bootstrap_external>", line 1133, in get_code
  File "<frozen importlib._bootstrap_external>", line 1063, in source_to_code
  File "<frozen importlib._bootstrap>", line 488, in _call_with_frames_removed
  File "/opt/airflow/dags/my_dag.py", line 4
    with DAG("my_dag",start_date) as dag:
                                         ^
IndentationError: expected an indented block after 'with' statement on line 4
[2024-12-16T18:01:59.205+0000] {processor.py:927} WARNING - No viable dags retrieved from /opt/airflow/dags/my_dag.py
[2024-12-16T18:01:59.508+0000] {processor.py:208} INFO - Processing /opt/airflow/dags/my_dag.py took 0.406 seconds
[2024-12-16T18:02:29.905+0000] {processor.py:186} INFO - Started process (PID=5331) to work on /opt/airflow/dags/my_dag.py
[2024-12-16T18:02:29.907+0000] {processor.py:914} INFO - Processing file /opt/airflow/dags/my_dag.py for tasks to queue
[2024-12-16T18:02:29.911+0000] {logging_mixin.py:190} INFO - [2024-12-16T18:02:29.910+0000] {dagbag.py:588} INFO - Filling up the DagBag from /opt/airflow/dags/my_dag.py
[2024-12-16T18:02:29.944+0000] {logging_mixin.py:190} INFO - [2024-12-16T18:02:29.941+0000] {dagbag.py:387} ERROR - Failed to import: /opt/airflow/dags/my_dag.py
Traceback (most recent call last):
  File "/home/airflow/.local/lib/python3.12/site-packages/airflow/models/dagbag.py", line 383, in parse
    loader.exec_module(new_module)
  File "<frozen importlib._bootstrap_external>", line 995, in exec_module
  File "<frozen importlib._bootstrap_external>", line 1133, in get_code
  File "<frozen importlib._bootstrap_external>", line 1063, in source_to_code
  File "<frozen importlib._bootstrap>", line 488, in _call_with_frames_removed
  File "/opt/airflow/dags/my_dag.py", line 4
    with DAG("my_dag",start_date) as dag:
                                         ^
IndentationError: expected an indented block after 'with' statement on line 4
[2024-12-16T18:02:29.946+0000] {processor.py:927} WARNING - No viable dags retrieved from /opt/airflow/dags/my_dag.py
[2024-12-16T18:02:31.204+0000] {processor.py:208} INFO - Processing /opt/airflow/dags/my_dag.py took 1.326 seconds
[2024-12-16T18:03:01.322+0000] {processor.py:186} INFO - Started process (PID=5395) to work on /opt/airflow/dags/my_dag.py
[2024-12-16T18:03:01.324+0000] {processor.py:914} INFO - Processing file /opt/airflow/dags/my_dag.py for tasks to queue
[2024-12-16T18:03:01.327+0000] {logging_mixin.py:190} INFO - [2024-12-16T18:03:01.327+0000] {dagbag.py:588} INFO - Filling up the DagBag from /opt/airflow/dags/my_dag.py
[2024-12-16T18:03:01.353+0000] {logging_mixin.py:190} INFO - [2024-12-16T18:03:01.350+0000] {dagbag.py:387} ERROR - Failed to import: /opt/airflow/dags/my_dag.py
Traceback (most recent call last):
  File "/home/airflow/.local/lib/python3.12/site-packages/airflow/models/dagbag.py", line 383, in parse
    loader.exec_module(new_module)
  File "<frozen importlib._bootstrap_external>", line 995, in exec_module
  File "<frozen importlib._bootstrap_external>", line 1133, in get_code
  File "<frozen importlib._bootstrap_external>", line 1063, in source_to_code
  File "<frozen importlib._bootstrap>", line 488, in _call_with_frames_removed
  File "/opt/airflow/dags/my_dag.py", line 4
    with DAG("my_dag",start_date) as dag:
                                         ^
IndentationError: expected an indented block after 'with' statement on line 4
[2024-12-16T18:03:01.354+0000] {processor.py:927} WARNING - No viable dags retrieved from /opt/airflow/dags/my_dag.py
[2024-12-16T18:03:01.434+0000] {processor.py:208} INFO - Processing /opt/airflow/dags/my_dag.py took 0.127 seconds
[2024-12-16T18:03:40.724+0000] {processor.py:186} INFO - Started process (PID=5450) to work on /opt/airflow/dags/my_dag.py
[2024-12-16T18:03:40.732+0000] {processor.py:914} INFO - Processing file /opt/airflow/dags/my_dag.py for tasks to queue
[2024-12-16T18:03:40.750+0000] {logging_mixin.py:190} INFO - [2024-12-16T18:03:40.749+0000] {dagbag.py:588} INFO - Filling up the DagBag from /opt/airflow/dags/my_dag.py
[2024-12-16T18:03:40.861+0000] {logging_mixin.py:190} INFO - [2024-12-16T18:03:40.859+0000] {dagbag.py:387} ERROR - Failed to import: /opt/airflow/dags/my_dag.py
Traceback (most recent call last):
  File "/home/airflow/.local/lib/python3.12/site-packages/airflow/models/dagbag.py", line 383, in parse
    loader.exec_module(new_module)
  File "<frozen importlib._bootstrap_external>", line 995, in exec_module
  File "<frozen importlib._bootstrap_external>", line 1133, in get_code
  File "<frozen importlib._bootstrap_external>", line 1063, in source_to_code
  File "<frozen importlib._bootstrap>", line 488, in _call_with_frames_removed
  File "/opt/airflow/dags/my_dag.py", line 4
    with DAG("my_dag",start_date=datetime(2024,)) as dag:
                                                         ^
IndentationError: expected an indented block after 'with' statement on line 4
[2024-12-16T18:03:40.863+0000] {processor.py:927} WARNING - No viable dags retrieved from /opt/airflow/dags/my_dag.py
[2024-12-16T18:03:41.033+0000] {processor.py:208} INFO - Processing /opt/airflow/dags/my_dag.py took 0.343 seconds
[2024-12-16T18:04:03.016+0000] {processor.py:186} INFO - Started process (PID=5502) to work on /opt/airflow/dags/my_dag.py
[2024-12-16T18:04:03.025+0000] {processor.py:914} INFO - Processing file /opt/airflow/dags/my_dag.py for tasks to queue
[2024-12-16T18:04:03.029+0000] {logging_mixin.py:190} INFO - [2024-12-16T18:04:03.028+0000] {dagbag.py:588} INFO - Filling up the DagBag from /opt/airflow/dags/my_dag.py
[2024-12-16T18:04:03.124+0000] {logging_mixin.py:190} INFO - [2024-12-16T18:04:03.114+0000] {dagbag.py:387} ERROR - Failed to import: /opt/airflow/dags/my_dag.py
Traceback (most recent call last):
  File "/home/airflow/.local/lib/python3.12/site-packages/airflow/models/dagbag.py", line 383, in parse
    loader.exec_module(new_module)
  File "<frozen importlib._bootstrap_external>", line 995, in exec_module
  File "<frozen importlib._bootstrap_external>", line 1133, in get_code
  File "<frozen importlib._bootstrap_external>", line 1063, in source_to_code
  File "<frozen importlib._bootstrap>", line 488, in _call_with_frames_removed
  File "/opt/airflow/dags/my_dag.py", line 4
    with DAG("my_dag",start_date=datetime(2024,12,16)) as dag:
                                                              ^
IndentationError: expected an indented block after 'with' statement on line 4
[2024-12-16T18:04:03.126+0000] {processor.py:927} WARNING - No viable dags retrieved from /opt/airflow/dags/my_dag.py
[2024-12-16T18:04:03.258+0000] {processor.py:208} INFO - Processing /opt/airflow/dags/my_dag.py took 0.265 seconds
[2024-12-16T18:04:24.939+0000] {processor.py:186} INFO - Started process (PID=5546) to work on /opt/airflow/dags/my_dag.py
[2024-12-16T18:04:24.941+0000] {processor.py:914} INFO - Processing file /opt/airflow/dags/my_dag.py for tasks to queue
[2024-12-16T18:04:24.943+0000] {logging_mixin.py:190} INFO - [2024-12-16T18:04:24.943+0000] {dagbag.py:588} INFO - Filling up the DagBag from /opt/airflow/dags/my_dag.py
[2024-12-16T18:04:24.963+0000] {logging_mixin.py:190} INFO - [2024-12-16T18:04:24.961+0000] {dagbag.py:387} ERROR - Failed to import: /opt/airflow/dags/my_dag.py
Traceback (most recent call last):
  File "/home/airflow/.local/lib/python3.12/site-packages/airflow/models/dagbag.py", line 383, in parse
    loader.exec_module(new_module)
  File "<frozen importlib._bootstrap_external>", line 995, in exec_module
  File "<frozen importlib._bootstrap_external>", line 1133, in get_code
  File "<frozen importlib._bootstrap_external>", line 1063, in source_to_code
  File "<frozen importlib._bootstrap>", line 488, in _call_with_frames_removed
  File "/opt/airflow/dags/my_dag.py", line 4
    with DAG("my_dag",start_date=datetime(2024,12,16),) as dag:
                                                               ^
IndentationError: expected an indented block after 'with' statement on line 4
[2024-12-16T18:04:24.965+0000] {processor.py:927} WARNING - No viable dags retrieved from /opt/airflow/dags/my_dag.py
[2024-12-16T18:04:25.252+0000] {processor.py:208} INFO - Processing /opt/airflow/dags/my_dag.py took 0.326 seconds
[2024-12-16T18:04:37.475+0000] {processor.py:186} INFO - Started process (PID=5569) to work on /opt/airflow/dags/my_dag.py
[2024-12-16T18:04:37.482+0000] {processor.py:914} INFO - Processing file /opt/airflow/dags/my_dag.py for tasks to queue
[2024-12-16T18:04:37.486+0000] {logging_mixin.py:190} INFO - [2024-12-16T18:04:37.485+0000] {dagbag.py:588} INFO - Filling up the DagBag from /opt/airflow/dags/my_dag.py
[2024-12-16T18:04:37.521+0000] {logging_mixin.py:190} INFO - [2024-12-16T18:04:37.517+0000] {dagbag.py:387} ERROR - Failed to import: /opt/airflow/dags/my_dag.py
Traceback (most recent call last):
  File "/home/airflow/.local/lib/python3.12/site-packages/airflow/models/dagbag.py", line 383, in parse
    loader.exec_module(new_module)
  File "<frozen importlib._bootstrap_external>", line 995, in exec_module
  File "<frozen importlib._bootstrap_external>", line 1133, in get_code
  File "<frozen importlib._bootstrap_external>", line 1063, in source_to_code
  File "<frozen importlib._bootstrap>", line 488, in _call_with_frames_removed
  File "/opt/airflow/dags/my_dag.py", line 4
    with DAG("my_dag",start_date=datetime(2024,12,16),schedue) as dag:
                                                             ^
SyntaxError: positional argument follows keyword argument
[2024-12-16T18:04:37.523+0000] {processor.py:927} WARNING - No viable dags retrieved from /opt/airflow/dags/my_dag.py
[2024-12-16T18:04:37.635+0000] {processor.py:208} INFO - Processing /opt/airflow/dags/my_dag.py took 0.181 seconds
[2024-12-16T18:04:43.417+0000] {processor.py:186} INFO - Started process (PID=5576) to work on /opt/airflow/dags/my_dag.py
[2024-12-16T18:04:43.463+0000] {processor.py:914} INFO - Processing file /opt/airflow/dags/my_dag.py for tasks to queue
[2024-12-16T18:04:43.468+0000] {logging_mixin.py:190} INFO - [2024-12-16T18:04:43.468+0000] {dagbag.py:588} INFO - Filling up the DagBag from /opt/airflow/dags/my_dag.py
[2024-12-16T18:04:43.527+0000] {logging_mixin.py:190} INFO - [2024-12-16T18:04:43.525+0000] {dagbag.py:387} ERROR - Failed to import: /opt/airflow/dags/my_dag.py
Traceback (most recent call last):
  File "/home/airflow/.local/lib/python3.12/site-packages/airflow/models/dagbag.py", line 383, in parse
    loader.exec_module(new_module)
  File "<frozen importlib._bootstrap_external>", line 995, in exec_module
  File "<frozen importlib._bootstrap_external>", line 1133, in get_code
  File "<frozen importlib._bootstrap_external>", line 1063, in source_to_code
  File "<frozen importlib._bootstrap>", line 488, in _call_with_frames_removed
  File "/opt/airflow/dags/my_dag.py", line 4
    with DAG("my_dag",start_date=datetime(2024,12,16),schedule_interval=) as dag:
                                                      ^^^^^^^^^^^^^^^^^^
SyntaxError: expected argument value expression
[2024-12-16T18:04:43.533+0000] {processor.py:927} WARNING - No viable dags retrieved from /opt/airflow/dags/my_dag.py
[2024-12-16T18:04:45.237+0000] {processor.py:208} INFO - Processing /opt/airflow/dags/my_dag.py took 1.842 seconds
[2024-12-16T18:04:55.553+0000] {processor.py:186} INFO - Started process (PID=5592) to work on /opt/airflow/dags/my_dag.py
[2024-12-16T18:04:55.556+0000] {processor.py:914} INFO - Processing file /opt/airflow/dags/my_dag.py for tasks to queue
[2024-12-16T18:04:55.560+0000] {logging_mixin.py:190} INFO - [2024-12-16T18:04:55.559+0000] {dagbag.py:588} INFO - Filling up the DagBag from /opt/airflow/dags/my_dag.py
[2024-12-16T18:04:55.600+0000] {logging_mixin.py:190} INFO - [2024-12-16T18:04:55.597+0000] {dagbag.py:387} ERROR - Failed to import: /opt/airflow/dags/my_dag.py
Traceback (most recent call last):
  File "/home/airflow/.local/lib/python3.12/site-packages/airflow/models/dagbag.py", line 383, in parse
    loader.exec_module(new_module)
  File "<frozen importlib._bootstrap_external>", line 995, in exec_module
  File "<frozen importlib._bootstrap_external>", line 1133, in get_code
  File "<frozen importlib._bootstrap_external>", line 1063, in source_to_code
  File "<frozen importlib._bootstrap>", line 488, in _call_with_frames_removed
  File "/opt/airflow/dags/my_dag.py", line 4
    with DAG("my_dag",start_date=datetime(2024,12,16),schedule_interval=@daily) as dag:
                                                                        ^
SyntaxError: invalid syntax
[2024-12-16T18:04:55.603+0000] {processor.py:927} WARNING - No viable dags retrieved from /opt/airflow/dags/my_dag.py
[2024-12-16T18:04:55.674+0000] {processor.py:208} INFO - Processing /opt/airflow/dags/my_dag.py took 0.136 seconds
[2024-12-16T18:05:07.940+0000] {processor.py:186} INFO - Started process (PID=5632) to work on /opt/airflow/dags/my_dag.py
[2024-12-16T18:05:08.012+0000] {processor.py:914} INFO - Processing file /opt/airflow/dags/my_dag.py for tasks to queue
[2024-12-16T18:05:08.096+0000] {logging_mixin.py:190} INFO - [2024-12-16T18:05:08.095+0000] {dagbag.py:588} INFO - Filling up the DagBag from /opt/airflow/dags/my_dag.py
[2024-12-16T18:05:08.655+0000] {logging_mixin.py:190} INFO - [2024-12-16T18:05:08.653+0000] {dagbag.py:387} ERROR - Failed to import: /opt/airflow/dags/my_dag.py
Traceback (most recent call last):
  File "/home/airflow/.local/lib/python3.12/site-packages/airflow/models/dagbag.py", line 383, in parse
    loader.exec_module(new_module)
  File "<frozen importlib._bootstrap_external>", line 995, in exec_module
  File "<frozen importlib._bootstrap_external>", line 1133, in get_code
  File "<frozen importlib._bootstrap_external>", line 1063, in source_to_code
  File "<frozen importlib._bootstrap>", line 488, in _call_with_frames_removed
  File "/opt/airflow/dags/my_dag.py", line 4
    with DAG("my_dag",start_date=datetime(2024,12,16),schedule_interval="@daily") as dag:
                                                                                         ^
IndentationError: expected an indented block after 'with' statement on line 4
[2024-12-16T18:05:08.657+0000] {processor.py:927} WARNING - No viable dags retrieved from /opt/airflow/dags/my_dag.py
[2024-12-16T18:05:10.183+0000] {processor.py:208} INFO - Processing /opt/airflow/dags/my_dag.py took 2.270 seconds
[2024-12-16T18:05:22.756+0000] {processor.py:186} INFO - Started process (PID=5647) to work on /opt/airflow/dags/my_dag.py
[2024-12-16T18:05:22.765+0000] {processor.py:914} INFO - Processing file /opt/airflow/dags/my_dag.py for tasks to queue
[2024-12-16T18:05:22.780+0000] {logging_mixin.py:190} INFO - [2024-12-16T18:05:22.779+0000] {dagbag.py:588} INFO - Filling up the DagBag from /opt/airflow/dags/my_dag.py
[2024-12-16T18:05:22.994+0000] {logging_mixin.py:190} INFO - [2024-12-16T18:05:22.992+0000] {dagbag.py:387} ERROR - Failed to import: /opt/airflow/dags/my_dag.py
Traceback (most recent call last):
  File "/home/airflow/.local/lib/python3.12/site-packages/airflow/models/dagbag.py", line 383, in parse
    loader.exec_module(new_module)
  File "<frozen importlib._bootstrap_external>", line 995, in exec_module
  File "<frozen importlib._bootstrap_external>", line 1133, in get_code
  File "<frozen importlib._bootstrap_external>", line 1063, in source_to_code
  File "<frozen importlib._bootstrap>", line 488, in _call_with_frames_removed
  File "/opt/airflow/dags/my_dag.py", line 4
    with DAG("my_dag",start_date=datetime(2024,12,16),schedule_interval="@daily",) as dag:
                                                                                          ^
IndentationError: expected an indented block after 'with' statement on line 4
[2024-12-16T18:05:22.999+0000] {processor.py:927} WARNING - No viable dags retrieved from /opt/airflow/dags/my_dag.py
[2024-12-16T18:05:23.345+0000] {processor.py:208} INFO - Processing /opt/airflow/dags/my_dag.py took 0.638 seconds
[2024-12-16T18:05:54.726+0000] {processor.py:186} INFO - Started process (PID=5710) to work on /opt/airflow/dags/my_dag.py
[2024-12-16T18:05:54.731+0000] {processor.py:914} INFO - Processing file /opt/airflow/dags/my_dag.py for tasks to queue
[2024-12-16T18:05:54.744+0000] {logging_mixin.py:190} INFO - [2024-12-16T18:05:54.743+0000] {dagbag.py:588} INFO - Filling up the DagBag from /opt/airflow/dags/my_dag.py
[2024-12-16T18:05:54.805+0000] {logging_mixin.py:190} INFO - [2024-12-16T18:05:54.802+0000] {dagbag.py:387} ERROR - Failed to import: /opt/airflow/dags/my_dag.py
Traceback (most recent call last):
  File "/home/airflow/.local/lib/python3.12/site-packages/airflow/models/dagbag.py", line 383, in parse
    loader.exec_module(new_module)
  File "<frozen importlib._bootstrap_external>", line 995, in exec_module
  File "<frozen importlib._bootstrap_external>", line 1133, in get_code
  File "<frozen importlib._bootstrap_external>", line 1063, in source_to_code
  File "<frozen importlib._bootstrap>", line 488, in _call_with_frames_removed
  File "/opt/airflow/dags/my_dag.py", line 4
    with DAG("my_dag",start_date=datetime(2024,12,16),schedule_interval="@daily",) as dag:
                                                                                          ^
IndentationError: expected an indented block after 'with' statement on line 4
[2024-12-16T18:05:54.815+0000] {processor.py:927} WARNING - No viable dags retrieved from /opt/airflow/dags/my_dag.py
[2024-12-16T18:05:54.969+0000] {processor.py:208} INFO - Processing /opt/airflow/dags/my_dag.py took 0.285 seconds
[2024-12-16T18:06:25.284+0000] {processor.py:186} INFO - Started process (PID=5772) to work on /opt/airflow/dags/my_dag.py
[2024-12-16T18:06:25.286+0000] {processor.py:914} INFO - Processing file /opt/airflow/dags/my_dag.py for tasks to queue
[2024-12-16T18:06:25.290+0000] {logging_mixin.py:190} INFO - [2024-12-16T18:06:25.289+0000] {dagbag.py:588} INFO - Filling up the DagBag from /opt/airflow/dags/my_dag.py
[2024-12-16T18:06:25.309+0000] {logging_mixin.py:190} INFO - [2024-12-16T18:06:25.307+0000] {dagbag.py:387} ERROR - Failed to import: /opt/airflow/dags/my_dag.py
Traceback (most recent call last):
  File "/home/airflow/.local/lib/python3.12/site-packages/airflow/models/dagbag.py", line 383, in parse
    loader.exec_module(new_module)
  File "<frozen importlib._bootstrap_external>", line 995, in exec_module
  File "<frozen importlib._bootstrap_external>", line 1133, in get_code
  File "<frozen importlib._bootstrap_external>", line 1063, in source_to_code
  File "<frozen importlib._bootstrap>", line 488, in _call_with_frames_removed
  File "/opt/airflow/dags/my_dag.py", line 4
    with DAG("my_dag",start_date=datetime(2024,12,16),schedule_interval="@daily",) as dag:
                                                                                          ^
IndentationError: expected an indented block after 'with' statement on line 4
[2024-12-16T18:06:25.310+0000] {processor.py:927} WARNING - No viable dags retrieved from /opt/airflow/dags/my_dag.py
[2024-12-16T18:06:25.390+0000] {processor.py:208} INFO - Processing /opt/airflow/dags/my_dag.py took 0.117 seconds
[2024-12-16T18:06:55.557+0000] {processor.py:186} INFO - Started process (PID=5836) to work on /opt/airflow/dags/my_dag.py
[2024-12-16T18:06:55.559+0000] {processor.py:914} INFO - Processing file /opt/airflow/dags/my_dag.py for tasks to queue
[2024-12-16T18:06:55.561+0000] {logging_mixin.py:190} INFO - [2024-12-16T18:06:55.561+0000] {dagbag.py:588} INFO - Filling up the DagBag from /opt/airflow/dags/my_dag.py
[2024-12-16T18:06:55.581+0000] {logging_mixin.py:190} INFO - [2024-12-16T18:06:55.579+0000] {dagbag.py:387} ERROR - Failed to import: /opt/airflow/dags/my_dag.py
Traceback (most recent call last):
  File "/home/airflow/.local/lib/python3.12/site-packages/airflow/models/dagbag.py", line 383, in parse
    loader.exec_module(new_module)
  File "<frozen importlib._bootstrap_external>", line 995, in exec_module
  File "<frozen importlib._bootstrap_external>", line 1133, in get_code
  File "<frozen importlib._bootstrap_external>", line 1063, in source_to_code
  File "<frozen importlib._bootstrap>", line 488, in _call_with_frames_removed
  File "/opt/airflow/dags/my_dag.py", line 4
    with DAG("my_dag",start_date=datetime(2024,12,16),schedule_interval="@daily",) as dag:
                                                                                          ^
IndentationError: expected an indented block after 'with' statement on line 4
[2024-12-16T18:06:55.582+0000] {processor.py:927} WARNING - No viable dags retrieved from /opt/airflow/dags/my_dag.py
[2024-12-16T18:06:55.675+0000] {processor.py:208} INFO - Processing /opt/airflow/dags/my_dag.py took 0.133 seconds
[2024-12-16T18:07:26.808+0000] {processor.py:186} INFO - Started process (PID=5880) to work on /opt/airflow/dags/my_dag.py
[2024-12-16T18:07:26.816+0000] {processor.py:914} INFO - Processing file /opt/airflow/dags/my_dag.py for tasks to queue
[2024-12-16T18:07:26.823+0000] {logging_mixin.py:190} INFO - [2024-12-16T18:07:26.822+0000] {dagbag.py:588} INFO - Filling up the DagBag from /opt/airflow/dags/my_dag.py
[2024-12-16T18:07:26.852+0000] {logging_mixin.py:190} INFO - [2024-12-16T18:07:26.849+0000] {dagbag.py:387} ERROR - Failed to import: /opt/airflow/dags/my_dag.py
Traceback (most recent call last):
  File "/home/airflow/.local/lib/python3.12/site-packages/airflow/models/dagbag.py", line 383, in parse
    loader.exec_module(new_module)
  File "<frozen importlib._bootstrap_external>", line 995, in exec_module
  File "<frozen importlib._bootstrap_external>", line 1133, in get_code
  File "<frozen importlib._bootstrap_external>", line 1063, in source_to_code
  File "<frozen importlib._bootstrap>", line 488, in _call_with_frames_removed
  File "/opt/airflow/dags/my_dag.py", line 4
    with DAG("my_dag",start_date=datetime(2024,12,16),schedule_interval="@daily",) as dag:
                                                                                          ^
IndentationError: expected an indented block after 'with' statement on line 4
[2024-12-16T18:07:26.859+0000] {processor.py:927} WARNING - No viable dags retrieved from /opt/airflow/dags/my_dag.py
[2024-12-16T18:07:27.066+0000] {processor.py:208} INFO - Processing /opt/airflow/dags/my_dag.py took 0.302 seconds
[2024-12-16T18:07:57.702+0000] {processor.py:186} INFO - Started process (PID=5941) to work on /opt/airflow/dags/my_dag.py
[2024-12-16T18:07:57.704+0000] {processor.py:914} INFO - Processing file /opt/airflow/dags/my_dag.py for tasks to queue
[2024-12-16T18:07:57.708+0000] {logging_mixin.py:190} INFO - [2024-12-16T18:07:57.707+0000] {dagbag.py:588} INFO - Filling up the DagBag from /opt/airflow/dags/my_dag.py
[2024-12-16T18:07:57.737+0000] {logging_mixin.py:190} INFO - [2024-12-16T18:07:57.735+0000] {dagbag.py:387} ERROR - Failed to import: /opt/airflow/dags/my_dag.py
Traceback (most recent call last):
  File "/home/airflow/.local/lib/python3.12/site-packages/airflow/models/dagbag.py", line 383, in parse
    loader.exec_module(new_module)
  File "<frozen importlib._bootstrap_external>", line 995, in exec_module
  File "<frozen importlib._bootstrap_external>", line 1133, in get_code
  File "<frozen importlib._bootstrap_external>", line 1063, in source_to_code
  File "<frozen importlib._bootstrap>", line 488, in _call_with_frames_removed
  File "/opt/airflow/dags/my_dag.py", line 4
    with DAG("my_dag",start_date=datetime(2024,12,16),schedule_interval="@daily",) as dag:
                                                                                          ^
IndentationError: expected an indented block after 'with' statement on line 4
[2024-12-16T18:07:57.739+0000] {processor.py:927} WARNING - No viable dags retrieved from /opt/airflow/dags/my_dag.py
[2024-12-16T18:07:57.830+0000] {processor.py:208} INFO - Processing /opt/airflow/dags/my_dag.py took 0.141 seconds
[2024-12-16T18:08:28.454+0000] {processor.py:186} INFO - Started process (PID=6005) to work on /opt/airflow/dags/my_dag.py
[2024-12-16T18:08:28.456+0000] {processor.py:914} INFO - Processing file /opt/airflow/dags/my_dag.py for tasks to queue
[2024-12-16T18:08:28.459+0000] {logging_mixin.py:190} INFO - [2024-12-16T18:08:28.458+0000] {dagbag.py:588} INFO - Filling up the DagBag from /opt/airflow/dags/my_dag.py
[2024-12-16T18:08:28.485+0000] {logging_mixin.py:190} INFO - [2024-12-16T18:08:28.482+0000] {dagbag.py:387} ERROR - Failed to import: /opt/airflow/dags/my_dag.py
Traceback (most recent call last):
  File "/home/airflow/.local/lib/python3.12/site-packages/airflow/models/dagbag.py", line 383, in parse
    loader.exec_module(new_module)
  File "<frozen importlib._bootstrap_external>", line 995, in exec_module
  File "<frozen importlib._bootstrap_external>", line 1133, in get_code
  File "<frozen importlib._bootstrap_external>", line 1063, in source_to_code
  File "<frozen importlib._bootstrap>", line 488, in _call_with_frames_removed
  File "/opt/airflow/dags/my_dag.py", line 4
    with DAG("my_dag",start_date=datetime(2024,12,16),schedule_interval="@daily",) as dag:
                                                                                          ^
IndentationError: expected an indented block after 'with' statement on line 4
[2024-12-16T18:08:28.487+0000] {processor.py:927} WARNING - No viable dags retrieved from /opt/airflow/dags/my_dag.py
[2024-12-16T18:08:28.564+0000] {processor.py:208} INFO - Processing /opt/airflow/dags/my_dag.py took 0.124 seconds
[2024-12-16T18:08:58.838+0000] {processor.py:186} INFO - Started process (PID=6068) to work on /opt/airflow/dags/my_dag.py
[2024-12-16T18:08:58.840+0000] {processor.py:914} INFO - Processing file /opt/airflow/dags/my_dag.py for tasks to queue
[2024-12-16T18:08:58.845+0000] {logging_mixin.py:190} INFO - [2024-12-16T18:08:58.844+0000] {dagbag.py:588} INFO - Filling up the DagBag from /opt/airflow/dags/my_dag.py
[2024-12-16T18:08:58.877+0000] {logging_mixin.py:190} INFO - [2024-12-16T18:08:58.875+0000] {dagbag.py:387} ERROR - Failed to import: /opt/airflow/dags/my_dag.py
Traceback (most recent call last):
  File "/home/airflow/.local/lib/python3.12/site-packages/airflow/models/dagbag.py", line 383, in parse
    loader.exec_module(new_module)
  File "<frozen importlib._bootstrap_external>", line 995, in exec_module
  File "<frozen importlib._bootstrap_external>", line 1133, in get_code
  File "<frozen importlib._bootstrap_external>", line 1063, in source_to_code
  File "<frozen importlib._bootstrap>", line 488, in _call_with_frames_removed
  File "/opt/airflow/dags/my_dag.py", line 4
    with DAG("my_dag",start_date=datetime(2024,12,16),schedule_interval="@daily",) as dag:
                                                                                          ^
IndentationError: expected an indented block after 'with' statement on line 4
[2024-12-16T18:08:58.878+0000] {processor.py:927} WARNING - No viable dags retrieved from /opt/airflow/dags/my_dag.py
[2024-12-16T18:08:59.880+0000] {processor.py:208} INFO - Processing /opt/airflow/dags/my_dag.py took 1.060 seconds
[2024-12-16T18:09:05.874+0000] {processor.py:186} INFO - Started process (PID=6086) to work on /opt/airflow/dags/my_dag.py
[2024-12-16T18:09:05.886+0000] {processor.py:914} INFO - Processing file /opt/airflow/dags/my_dag.py for tasks to queue
[2024-12-16T18:09:05.898+0000] {logging_mixin.py:190} INFO - [2024-12-16T18:09:05.897+0000] {dagbag.py:588} INFO - Filling up the DagBag from /opt/airflow/dags/my_dag.py
[2024-12-16T18:09:05.961+0000] {logging_mixin.py:190} INFO - [2024-12-16T18:09:05.958+0000] {dagbag.py:387} ERROR - Failed to import: /opt/airflow/dags/my_dag.py
Traceback (most recent call last):
  File "/home/airflow/.local/lib/python3.12/site-packages/airflow/models/dagbag.py", line 383, in parse
    loader.exec_module(new_module)
  File "<frozen importlib._bootstrap_external>", line 995, in exec_module
  File "<frozen importlib._bootstrap_external>", line 1133, in get_code
  File "<frozen importlib._bootstrap_external>", line 1063, in source_to_code
  File "<frozen importlib._bootstrap>", line 488, in _call_with_frames_removed
  File "/opt/airflow/dags/my_dag.py", line 2
    from datetime import datetime,
                                  ^
SyntaxError: trailing comma not allowed without surrounding parentheses
[2024-12-16T18:09:05.963+0000] {processor.py:927} WARNING - No viable dags retrieved from /opt/airflow/dags/my_dag.py
[2024-12-16T18:09:06.111+0000] {processor.py:208} INFO - Processing /opt/airflow/dags/my_dag.py took 0.276 seconds
[2024-12-16T18:09:36.759+0000] {processor.py:186} INFO - Started process (PID=6150) to work on /opt/airflow/dags/my_dag.py
[2024-12-16T18:09:36.760+0000] {processor.py:914} INFO - Processing file /opt/airflow/dags/my_dag.py for tasks to queue
[2024-12-16T18:09:36.764+0000] {logging_mixin.py:190} INFO - [2024-12-16T18:09:36.763+0000] {dagbag.py:588} INFO - Filling up the DagBag from /opt/airflow/dags/my_dag.py
[2024-12-16T18:09:36.783+0000] {logging_mixin.py:190} INFO - [2024-12-16T18:09:36.781+0000] {dagbag.py:387} ERROR - Failed to import: /opt/airflow/dags/my_dag.py
Traceback (most recent call last):
  File "/home/airflow/.local/lib/python3.12/site-packages/airflow/models/dagbag.py", line 383, in parse
    loader.exec_module(new_module)
  File "<frozen importlib._bootstrap_external>", line 995, in exec_module
  File "<frozen importlib._bootstrap_external>", line 1133, in get_code
  File "<frozen importlib._bootstrap_external>", line 1063, in source_to_code
  File "<frozen importlib._bootstrap>", line 488, in _call_with_frames_removed
  File "/opt/airflow/dags/my_dag.py", line 2
    from datetime import datetime,
                                  ^
SyntaxError: trailing comma not allowed without surrounding parentheses
[2024-12-16T18:09:36.784+0000] {processor.py:927} WARNING - No viable dags retrieved from /opt/airflow/dags/my_dag.py
[2024-12-16T18:09:36.862+0000] {processor.py:208} INFO - Processing /opt/airflow/dags/my_dag.py took 0.123 seconds
[2024-12-16T18:09:39.618+0000] {processor.py:186} INFO - Started process (PID=6157) to work on /opt/airflow/dags/my_dag.py
[2024-12-16T18:09:39.620+0000] {processor.py:914} INFO - Processing file /opt/airflow/dags/my_dag.py for tasks to queue
[2024-12-16T18:09:39.662+0000] {logging_mixin.py:190} INFO - [2024-12-16T18:09:39.662+0000] {dagbag.py:588} INFO - Filling up the DagBag from /opt/airflow/dags/my_dag.py
[2024-12-16T18:09:39.785+0000] {logging_mixin.py:190} INFO - [2024-12-16T18:09:39.782+0000] {dagbag.py:387} ERROR - Failed to import: /opt/airflow/dags/my_dag.py
Traceback (most recent call last):
  File "/home/airflow/.local/lib/python3.12/site-packages/airflow/models/dagbag.py", line 383, in parse
    loader.exec_module(new_module)
  File "<frozen importlib._bootstrap_external>", line 995, in exec_module
  File "<frozen importlib._bootstrap_external>", line 1133, in get_code
  File "<frozen importlib._bootstrap_external>", line 1063, in source_to_code
  File "<frozen importlib._bootstrap>", line 488, in _call_with_frames_removed
  File "/opt/airflow/dags/my_dag.py", line 4
    with DAG("my_dag",start_date=datetime(2024,12,16),schedule_interval="*/2 * * * *",) as dag:
                                                                                               ^
IndentationError: expected an indented block after 'with' statement on line 4
[2024-12-16T18:09:39.788+0000] {processor.py:927} WARNING - No viable dags retrieved from /opt/airflow/dags/my_dag.py
[2024-12-16T18:09:39.998+0000] {processor.py:208} INFO - Processing /opt/airflow/dags/my_dag.py took 0.403 seconds
[2024-12-16T18:10:07.975+0000] {processor.py:186} INFO - Started process (PID=6216) to work on /opt/airflow/dags/my_dag.py
[2024-12-16T18:10:07.976+0000] {processor.py:914} INFO - Processing file /opt/airflow/dags/my_dag.py for tasks to queue
[2024-12-16T18:10:07.979+0000] {logging_mixin.py:190} INFO - [2024-12-16T18:10:07.978+0000] {dagbag.py:588} INFO - Filling up the DagBag from /opt/airflow/dags/my_dag.py
[2024-12-16T18:10:08.003+0000] {logging_mixin.py:190} INFO - [2024-12-16T18:10:08.001+0000] {dagbag.py:387} ERROR - Failed to import: /opt/airflow/dags/my_dag.py
Traceback (most recent call last):
  File "/home/airflow/.local/lib/python3.12/site-packages/airflow/models/dagbag.py", line 383, in parse
    loader.exec_module(new_module)
  File "<frozen importlib._bootstrap_external>", line 995, in exec_module
  File "<frozen importlib._bootstrap_external>", line 1133, in get_code
  File "<frozen importlib._bootstrap_external>", line 1063, in source_to_code
  File "<frozen importlib._bootstrap>", line 488, in _call_with_frames_removed
  File "/opt/airflow/dags/my_dag.py", line 4
    with DAG("my_dag",start_date=datetime(2024,12,16),schedule_interval="*/2 * * * *",catchup=False) as dag:
                                                                                                            ^
IndentationError: expected an indented block after 'with' statement on line 4
[2024-12-16T18:10:08.005+0000] {processor.py:927} WARNING - No viable dags retrieved from /opt/airflow/dags/my_dag.py
[2024-12-16T18:10:08.384+0000] {processor.py:208} INFO - Processing /opt/airflow/dags/my_dag.py took 0.423 seconds
[2024-12-16T18:10:39.936+0000] {processor.py:186} INFO - Started process (PID=6280) to work on /opt/airflow/dags/my_dag.py
[2024-12-16T18:10:39.938+0000] {processor.py:914} INFO - Processing file /opt/airflow/dags/my_dag.py for tasks to queue
[2024-12-16T18:10:39.951+0000] {logging_mixin.py:190} INFO - [2024-12-16T18:10:39.941+0000] {dagbag.py:588} INFO - Filling up the DagBag from /opt/airflow/dags/my_dag.py
[2024-12-16T18:10:40.015+0000] {logging_mixin.py:190} INFO - [2024-12-16T18:10:40.003+0000] {dagbag.py:387} ERROR - Failed to import: /opt/airflow/dags/my_dag.py
Traceback (most recent call last):
  File "/home/airflow/.local/lib/python3.12/site-packages/airflow/models/dagbag.py", line 383, in parse
    loader.exec_module(new_module)
  File "<frozen importlib._bootstrap_external>", line 995, in exec_module
  File "<frozen importlib._bootstrap_external>", line 1133, in get_code
  File "<frozen importlib._bootstrap_external>", line 1063, in source_to_code
  File "<frozen importlib._bootstrap>", line 488, in _call_with_frames_removed
  File "/opt/airflow/dags/my_dag.py", line 4
    with DAG("my_dag",start_date=datetime(2024,12,16),schedule_interval="*/2 * * * *",catchup=False) as dag:
                                                                                                            ^
IndentationError: expected an indented block after 'with' statement on line 4
[2024-12-16T18:10:40.019+0000] {processor.py:927} WARNING - No viable dags retrieved from /opt/airflow/dags/my_dag.py
[2024-12-16T18:10:40.794+0000] {processor.py:208} INFO - Processing /opt/airflow/dags/my_dag.py took 0.920 seconds
[2024-12-16T18:11:05.973+0000] {processor.py:186} INFO - Started process (PID=6323) to work on /opt/airflow/dags/my_dag.py
[2024-12-16T18:11:05.975+0000] {processor.py:914} INFO - Processing file /opt/airflow/dags/my_dag.py for tasks to queue
[2024-12-16T18:11:05.979+0000] {logging_mixin.py:190} INFO - [2024-12-16T18:11:05.978+0000] {dagbag.py:588} INFO - Filling up the DagBag from /opt/airflow/dags/my_dag.py
[2024-12-16T18:11:06.049+0000] {logging_mixin.py:190} INFO - [2024-12-16T18:11:06.044+0000] {dagbag.py:387} ERROR - Failed to import: /opt/airflow/dags/my_dag.py
Traceback (most recent call last):
  File "/home/airflow/.local/lib/python3.12/site-packages/airflow/models/dagbag.py", line 383, in parse
    loader.exec_module(new_module)
  File "<frozen importlib._bootstrap_external>", line 995, in exec_module
  File "<frozen importlib._bootstrap_external>", line 1133, in get_code
  File "<frozen importlib._bootstrap_external>", line 1063, in source_to_code
  File "<frozen importlib._bootstrap>", line 488, in _call_with_frames_removed
  File "/opt/airflow/dags/my_dag.py", line 6
    
    ^
IndentationError: expected an indented block after 'with' statement on line 4
[2024-12-16T18:11:06.051+0000] {processor.py:927} WARNING - No viable dags retrieved from /opt/airflow/dags/my_dag.py
[2024-12-16T18:11:06.457+0000] {processor.py:208} INFO - Processing /opt/airflow/dags/my_dag.py took 0.520 seconds
[2024-12-16T18:11:32.840+0000] {processor.py:186} INFO - Started process (PID=6362) to work on /opt/airflow/dags/my_dag.py
[2024-12-16T18:11:32.842+0000] {processor.py:914} INFO - Processing file /opt/airflow/dags/my_dag.py for tasks to queue
[2024-12-16T18:11:32.846+0000] {logging_mixin.py:190} INFO - [2024-12-16T18:11:32.845+0000] {dagbag.py:588} INFO - Filling up the DagBag from /opt/airflow/dags/my_dag.py
[2024-12-16T18:11:32.898+0000] {logging_mixin.py:190} INFO - [2024-12-16T18:11:32.895+0000] {dagbag.py:387} ERROR - Failed to import: /opt/airflow/dags/my_dag.py
Traceback (most recent call last):
  File "/home/airflow/.local/lib/python3.12/site-packages/airflow/models/dagbag.py", line 383, in parse
    loader.exec_module(new_module)
  File "<frozen importlib._bootstrap_external>", line 995, in exec_module
  File "<frozen importlib._bootstrap_external>", line 1133, in get_code
  File "<frozen importlib._bootstrap_external>", line 1063, in source_to_code
  File "<frozen importlib._bootstrap>", line 488, in _call_with_frames_removed
  File "/opt/airflow/dags/my_dag.py", line 2
    from airflow.
                 ^
SyntaxError: invalid syntax
[2024-12-16T18:11:32.900+0000] {processor.py:927} WARNING - No viable dags retrieved from /opt/airflow/dags/my_dag.py
[2024-12-16T18:11:34.124+0000] {processor.py:208} INFO - Processing /opt/airflow/dags/my_dag.py took 1.318 seconds
[2024-12-16T18:11:45.416+0000] {processor.py:186} INFO - Started process (PID=6389) to work on /opt/airflow/dags/my_dag.py
[2024-12-16T18:11:45.418+0000] {processor.py:914} INFO - Processing file /opt/airflow/dags/my_dag.py for tasks to queue
[2024-12-16T18:11:45.421+0000] {logging_mixin.py:190} INFO - [2024-12-16T18:11:45.420+0000] {dagbag.py:588} INFO - Filling up the DagBag from /opt/airflow/dags/my_dag.py
[2024-12-16T18:11:45.503+0000] {logging_mixin.py:190} INFO - [2024-12-16T18:11:45.501+0000] {dagbag.py:387} ERROR - Failed to import: /opt/airflow/dags/my_dag.py
Traceback (most recent call last):
  File "/home/airflow/.local/lib/python3.12/site-packages/airflow/models/dagbag.py", line 383, in parse
    loader.exec_module(new_module)
  File "<frozen importlib._bootstrap_external>", line 995, in exec_module
  File "<frozen importlib._bootstrap_external>", line 1133, in get_code
  File "<frozen importlib._bootstrap_external>", line 1063, in source_to_code
  File "<frozen importlib._bootstrap>", line 488, in _call_with_frames_removed
  File "/opt/airflow/dags/my_dag.py", line 2
    from airflow.operators.python 
                                  ^
SyntaxError: invalid syntax
[2024-12-16T18:11:45.505+0000] {processor.py:927} WARNING - No viable dags retrieved from /opt/airflow/dags/my_dag.py
[2024-12-16T18:11:45.788+0000] {processor.py:208} INFO - Processing /opt/airflow/dags/my_dag.py took 0.393 seconds
[2024-12-16T18:11:51.661+0000] {processor.py:186} INFO - Started process (PID=6401) to work on /opt/airflow/dags/my_dag.py
[2024-12-16T18:11:51.668+0000] {processor.py:914} INFO - Processing file /opt/airflow/dags/my_dag.py for tasks to queue
[2024-12-16T18:11:51.686+0000] {logging_mixin.py:190} INFO - [2024-12-16T18:11:51.685+0000] {dagbag.py:588} INFO - Filling up the DagBag from /opt/airflow/dags/my_dag.py
[2024-12-16T18:11:51.762+0000] {logging_mixin.py:190} INFO - [2024-12-16T18:11:51.760+0000] {dagbag.py:387} ERROR - Failed to import: /opt/airflow/dags/my_dag.py
Traceback (most recent call last):
  File "/home/airflow/.local/lib/python3.12/site-packages/airflow/models/dagbag.py", line 383, in parse
    loader.exec_module(new_module)
  File "<frozen importlib._bootstrap_external>", line 995, in exec_module
  File "<frozen importlib._bootstrap_external>", line 1133, in get_code
  File "<frozen importlib._bootstrap_external>", line 1063, in source_to_code
  File "<frozen importlib._bootstrap>", line 488, in _call_with_frames_removed
  File "/opt/airflow/dags/my_dag.py", line 6
    schedule_interval="*/2 * * * *",catchup=False) as dag:
                                                          ^
IndentationError: expected an indented block after 'with' statement on line 5
[2024-12-16T18:11:51.764+0000] {processor.py:927} WARNING - No viable dags retrieved from /opt/airflow/dags/my_dag.py
[2024-12-16T18:11:53.030+0000] {processor.py:208} INFO - Processing /opt/airflow/dags/my_dag.py took 1.395 seconds
[2024-12-16T18:11:59.971+0000] {processor.py:186} INFO - Started process (PID=6419) to work on /opt/airflow/dags/my_dag.py
[2024-12-16T18:11:59.973+0000] {processor.py:914} INFO - Processing file /opt/airflow/dags/my_dag.py for tasks to queue
[2024-12-16T18:11:59.976+0000] {logging_mixin.py:190} INFO - [2024-12-16T18:11:59.975+0000] {dagbag.py:588} INFO - Filling up the DagBag from /opt/airflow/dags/my_dag.py
[2024-12-16T18:12:00.061+0000] {logging_mixin.py:190} INFO - [2024-12-16T18:12:00.047+0000] {dagbag.py:387} ERROR - Failed to import: /opt/airflow/dags/my_dag.py
Traceback (most recent call last):
  File "/home/airflow/.local/lib/python3.12/site-packages/airflow/models/dagbag.py", line 383, in parse
    loader.exec_module(new_module)
  File "<frozen importlib._bootstrap_external>", line 995, in exec_module
  File "<frozen importlib._bootstrap_external>", line 1133, in get_code
  File "<frozen importlib._bootstrap_external>", line 1063, in source_to_code
  File "<frozen importlib._bootstrap>", line 488, in _call_with_frames_removed
  File "/opt/airflow/dags/my_dag.py", line 6
    schedule_interval="*/2 * * * *",catchup=False) as dag:
                                                          ^
IndentationError: expected an indented block after 'with' statement on line 5
[2024-12-16T18:12:00.062+0000] {processor.py:927} WARNING - No viable dags retrieved from /opt/airflow/dags/my_dag.py
[2024-12-16T18:12:00.136+0000] {processor.py:208} INFO - Processing /opt/airflow/dags/my_dag.py took 0.178 seconds
[2024-12-16T18:12:30.926+0000] {processor.py:186} INFO - Started process (PID=6481) to work on /opt/airflow/dags/my_dag.py
[2024-12-16T18:12:30.928+0000] {processor.py:914} INFO - Processing file /opt/airflow/dags/my_dag.py for tasks to queue
[2024-12-16T18:12:30.932+0000] {logging_mixin.py:190} INFO - [2024-12-16T18:12:30.931+0000] {dagbag.py:588} INFO - Filling up the DagBag from /opt/airflow/dags/my_dag.py
[2024-12-16T18:12:30.986+0000] {logging_mixin.py:190} INFO - [2024-12-16T18:12:30.983+0000] {dagbag.py:387} ERROR - Failed to import: /opt/airflow/dags/my_dag.py
Traceback (most recent call last):
  File "/home/airflow/.local/lib/python3.12/site-packages/airflow/models/dagbag.py", line 383, in parse
    loader.exec_module(new_module)
  File "<frozen importlib._bootstrap_external>", line 995, in exec_module
  File "<frozen importlib._bootstrap_external>", line 1133, in get_code
  File "<frozen importlib._bootstrap_external>", line 1063, in source_to_code
  File "<frozen importlib._bootstrap>", line 488, in _call_with_frames_removed
  File "/opt/airflow/dags/my_dag.py", line 6
    schedule_interval="*/2 * * * *",catchup=False) as dag:
                                                          ^
IndentationError: expected an indented block after 'with' statement on line 5
[2024-12-16T18:12:30.987+0000] {processor.py:927} WARNING - No viable dags retrieved from /opt/airflow/dags/my_dag.py
[2024-12-16T18:12:31.084+0000] {processor.py:208} INFO - Processing /opt/airflow/dags/my_dag.py took 0.177 seconds
[2024-12-16T18:12:40.510+0000] {processor.py:186} INFO - Started process (PID=6507) to work on /opt/airflow/dags/my_dag.py
[2024-12-16T18:12:40.513+0000] {processor.py:914} INFO - Processing file /opt/airflow/dags/my_dag.py for tasks to queue
[2024-12-16T18:12:40.517+0000] {logging_mixin.py:190} INFO - [2024-12-16T18:12:40.516+0000] {dagbag.py:588} INFO - Filling up the DagBag from /opt/airflow/dags/my_dag.py
[2024-12-16T18:12:40.556+0000] {logging_mixin.py:190} INFO - [2024-12-16T18:12:40.553+0000] {dagbag.py:387} ERROR - Failed to import: /opt/airflow/dags/my_dag.py
Traceback (most recent call last):
  File "/home/airflow/.local/lib/python3.12/site-packages/airflow/models/dagbag.py", line 383, in parse
    loader.exec_module(new_module)
  File "<frozen importlib._bootstrap_external>", line 995, in exec_module
  File "<frozen importlib._bootstrap_external>", line 1133, in get_code
  File "<frozen importlib._bootstrap_external>", line 1063, in source_to_code
  File "<frozen importlib._bootstrap>", line 488, in _call_with_frames_removed
  File "/opt/airflow/dags/my_dag.py", line 9
    
    ^
IndentationError: expected an indented block after 'with' statement on line 5
[2024-12-16T18:12:40.563+0000] {processor.py:927} WARNING - No viable dags retrieved from /opt/airflow/dags/my_dag.py
[2024-12-16T18:12:40.719+0000] {processor.py:208} INFO - Processing /opt/airflow/dags/my_dag.py took 0.226 seconds
[2024-12-16T18:12:56.053+0000] {processor.py:186} INFO - Started process (PID=6529) to work on /opt/airflow/dags/my_dag.py
[2024-12-16T18:12:56.081+0000] {processor.py:914} INFO - Processing file /opt/airflow/dags/my_dag.py for tasks to queue
[2024-12-16T18:12:56.097+0000] {logging_mixin.py:190} INFO - [2024-12-16T18:12:56.096+0000] {dagbag.py:588} INFO - Filling up the DagBag from /opt/airflow/dags/my_dag.py
[2024-12-16T18:12:56.620+0000] {logging_mixin.py:190} INFO - [2024-12-16T18:12:56.587+0000] {dagbag.py:387} ERROR - Failed to import: /opt/airflow/dags/my_dag.py
Traceback (most recent call last):
  File "/home/airflow/.local/lib/python3.12/site-packages/airflow/models/dagbag.py", line 383, in parse
    loader.exec_module(new_module)
  File "<frozen importlib._bootstrap_external>", line 999, in exec_module
  File "<frozen importlib._bootstrap>", line 488, in _call_with_frames_removed
  File "/opt/airflow/dags/my_dag.py", line 8, in <module>
    training_model
NameError: name 'training_model' is not defined
[2024-12-16T18:12:56.679+0000] {processor.py:927} WARNING - No viable dags retrieved from /opt/airflow/dags/my_dag.py
[2024-12-16T18:12:56.871+0000] {processor.py:208} INFO - Processing /opt/airflow/dags/my_dag.py took 0.842 seconds
[2024-12-16T18:12:57.941+0000] {processor.py:186} INFO - Started process (PID=6533) to work on /opt/airflow/dags/my_dag.py
[2024-12-16T18:12:57.944+0000] {processor.py:914} INFO - Processing file /opt/airflow/dags/my_dag.py for tasks to queue
[2024-12-16T18:12:57.947+0000] {logging_mixin.py:190} INFO - [2024-12-16T18:12:57.946+0000] {dagbag.py:588} INFO - Filling up the DagBag from /opt/airflow/dags/my_dag.py
[2024-12-16T18:12:58.553+0000] {logging_mixin.py:190} INFO - [2024-12-16T18:12:58.550+0000] {dagbag.py:387} ERROR - Failed to import: /opt/airflow/dags/my_dag.py
Traceback (most recent call last):
  File "/home/airflow/.local/lib/python3.12/site-packages/airflow/models/dagbag.py", line 383, in parse
    loader.exec_module(new_module)
  File "<frozen importlib._bootstrap_external>", line 995, in exec_module
  File "<frozen importlib._bootstrap_external>", line 1133, in get_code
  File "<frozen importlib._bootstrap_external>", line 1063, in source_to_code
  File "<frozen importlib._bootstrap>", line 488, in _call_with_frames_removed
  File "/opt/airflow/dags/my_dag.py", line 8
    training_model_A = 
                       ^
SyntaxError: invalid syntax
[2024-12-16T18:12:58.582+0000] {processor.py:927} WARNING - No viable dags retrieved from /opt/airflow/dags/my_dag.py
[2024-12-16T18:12:58.770+0000] {processor.py:208} INFO - Processing /opt/airflow/dags/my_dag.py took 0.847 seconds
[2024-12-16T18:13:27.455+0000] {processor.py:186} INFO - Started process (PID=6582) to work on /opt/airflow/dags/my_dag.py
[2024-12-16T18:13:27.569+0000] {processor.py:914} INFO - Processing file /opt/airflow/dags/my_dag.py for tasks to queue
[2024-12-16T18:13:27.575+0000] {logging_mixin.py:190} INFO - [2024-12-16T18:13:27.574+0000] {dagbag.py:588} INFO - Filling up the DagBag from /opt/airflow/dags/my_dag.py
[2024-12-16T18:13:27.973+0000] {processor.py:925} INFO - DAG(s) 'my_dag' retrieved from /opt/airflow/dags/my_dag.py
[2024-12-16T18:13:28.440+0000] {logging_mixin.py:190} INFO - [2024-12-16T18:13:28.436+0000] {override.py:1911} INFO - Created Permission View: can read on DAG:my_dag
[2024-12-16T18:13:28.584+0000] {logging_mixin.py:190} INFO - [2024-12-16T18:13:28.583+0000] {override.py:1911} INFO - Created Permission View: can delete on DAG:my_dag
[2024-12-16T18:13:28.763+0000] {logging_mixin.py:190} INFO - [2024-12-16T18:13:28.762+0000] {override.py:1911} INFO - Created Permission View: can edit on DAG:my_dag
[2024-12-16T18:13:28.956+0000] {logging_mixin.py:190} INFO - [2024-12-16T18:13:28.955+0000] {override.py:1911} INFO - Created Permission View: can read on DAG Run:my_dag
[2024-12-16T18:13:29.044+0000] {logging_mixin.py:190} INFO - [2024-12-16T18:13:29.043+0000] {override.py:1911} INFO - Created Permission View: can delete on DAG Run:my_dag
[2024-12-16T18:13:29.144+0000] {logging_mixin.py:190} INFO - [2024-12-16T18:13:29.143+0000] {override.py:1911} INFO - Created Permission View: menu access on DAG Run:my_dag
[2024-12-16T18:13:29.216+0000] {logging_mixin.py:190} INFO - [2024-12-16T18:13:29.216+0000] {override.py:1911} INFO - Created Permission View: can create on DAG Run:my_dag
[2024-12-16T18:13:29.218+0000] {logging_mixin.py:190} INFO - [2024-12-16T18:13:29.217+0000] {dag.py:3239} INFO - Sync 1 DAGs
[2024-12-16T18:13:29.242+0000] {logging_mixin.py:190} INFO - [2024-12-16T18:13:29.242+0000] {dag.py:3262} INFO - Creating ORM DAG for my_dag
[2024-12-16T18:13:29.266+0000] {logging_mixin.py:190} INFO - [2024-12-16T18:13:29.265+0000] {dag.py:4180} INFO - Setting next_dagrun for my_dag to 2024-12-16 18:10:00+00:00, run_after=2024-12-16 18:12:00+00:00
[2024-12-16T18:13:29.421+0000] {processor.py:208} INFO - Processing /opt/airflow/dags/my_dag.py took 1.992 seconds
[2024-12-16T18:13:48.189+0000] {processor.py:186} INFO - Started process (PID=6622) to work on /opt/airflow/dags/my_dag.py
[2024-12-16T18:13:48.194+0000] {processor.py:914} INFO - Processing file /opt/airflow/dags/my_dag.py for tasks to queue
[2024-12-16T18:13:48.198+0000] {logging_mixin.py:190} INFO - [2024-12-16T18:13:48.198+0000] {dagbag.py:588} INFO - Filling up the DagBag from /opt/airflow/dags/my_dag.py
[2024-12-16T18:13:49.576+0000] {logging_mixin.py:190} INFO - [2024-12-16T18:13:49.134+0000] {dagbag.py:387} ERROR - Failed to import: /opt/airflow/dags/my_dag.py
Traceback (most recent call last):
  File "/home/airflow/.local/lib/python3.12/site-packages/airflow/models/dagbag.py", line 383, in parse
    loader.exec_module(new_module)
  File "<frozen importlib._bootstrap_external>", line 999, in exec_module
  File "<frozen importlib._bootstrap>", line 488, in _call_with_frames_removed
  File "/opt/airflow/dags/my_dag.py", line 8, in <module>
    training_model_A = PythonOperator(
                       ^^^^^^^^^^^^^^^
  File "/home/airflow/.local/lib/python3.12/site-packages/airflow/models/baseoperator.py", line 489, in apply_defaults
    raise AirflowException(f"missing keyword argument {missing_args.pop()!r}")
airflow.exceptions.AirflowException: missing keyword argument 'python_callable'
[2024-12-16T18:13:49.579+0000] {processor.py:927} WARNING - No viable dags retrieved from /opt/airflow/dags/my_dag.py
[2024-12-16T18:13:50.158+0000] {processor.py:208} INFO - Processing /opt/airflow/dags/my_dag.py took 1.996 seconds
[2024-12-16T18:14:06.868+0000] {processor.py:186} INFO - Started process (PID=6645) to work on /opt/airflow/dags/my_dag.py
[2024-12-16T18:14:06.869+0000] {processor.py:914} INFO - Processing file /opt/airflow/dags/my_dag.py for tasks to queue
[2024-12-16T18:14:06.871+0000] {logging_mixin.py:190} INFO - [2024-12-16T18:14:06.871+0000] {dagbag.py:588} INFO - Filling up the DagBag from /opt/airflow/dags/my_dag.py
[2024-12-16T18:14:06.912+0000] {logging_mixin.py:190} INFO - [2024-12-16T18:14:06.902+0000] {dagbag.py:387} ERROR - Failed to import: /opt/airflow/dags/my_dag.py
Traceback (most recent call last):
  File "/home/airflow/.local/lib/python3.12/site-packages/airflow/models/dagbag.py", line 383, in parse
    loader.exec_module(new_module)
  File "<frozen importlib._bootstrap_external>", line 999, in exec_module
  File "<frozen importlib._bootstrap>", line 488, in _call_with_frames_removed
  File "/opt/airflow/dags/my_dag.py", line 9, in <module>
    task_id
NameError: name 'task_id' is not defined
[2024-12-16T18:14:06.918+0000] {processor.py:927} WARNING - No viable dags retrieved from /opt/airflow/dags/my_dag.py
[2024-12-16T18:14:07.391+0000] {processor.py:208} INFO - Processing /opt/airflow/dags/my_dag.py took 0.535 seconds
[2024-12-16T18:14:44.211+0000] {processor.py:186} INFO - Started process (PID=6695) to work on /opt/airflow/dags/my_dag.py
[2024-12-16T18:14:44.215+0000] {processor.py:914} INFO - Processing file /opt/airflow/dags/my_dag.py for tasks to queue
[2024-12-16T18:14:44.217+0000] {logging_mixin.py:190} INFO - [2024-12-16T18:14:44.217+0000] {dagbag.py:588} INFO - Filling up the DagBag from /opt/airflow/dags/my_dag.py
[2024-12-16T18:14:44.246+0000] {logging_mixin.py:190} INFO - [2024-12-16T18:14:44.244+0000] {dagbag.py:387} ERROR - Failed to import: /opt/airflow/dags/my_dag.py
Traceback (most recent call last):
  File "/home/airflow/.local/lib/python3.12/site-packages/airflow/models/dagbag.py", line 383, in parse
    loader.exec_module(new_module)
  File "<frozen importlib._bootstrap_external>", line 995, in exec_module
  File "<frozen importlib._bootstrap_external>", line 1133, in get_code
  File "<frozen importlib._bootstrap_external>", line 1063, in source_to_code
  File "<frozen importlib._bootstrap>", line 488, in _call_with_frames_removed
  File "/opt/airflow/dags/my_dag.py", line 9
    task_id = 
    ^^^^^^^^^
SyntaxError: expected argument value expression
[2024-12-16T18:14:44.247+0000] {processor.py:927} WARNING - No viable dags retrieved from /opt/airflow/dags/my_dag.py
[2024-12-16T18:14:45.289+0000] {processor.py:208} INFO - Processing /opt/airflow/dags/my_dag.py took 1.093 seconds
[2024-12-16T18:15:15.625+0000] {processor.py:186} INFO - Started process (PID=6757) to work on /opt/airflow/dags/my_dag.py
[2024-12-16T18:15:15.626+0000] {processor.py:914} INFO - Processing file /opt/airflow/dags/my_dag.py for tasks to queue
[2024-12-16T18:15:15.629+0000] {logging_mixin.py:190} INFO - [2024-12-16T18:15:15.628+0000] {dagbag.py:588} INFO - Filling up the DagBag from /opt/airflow/dags/my_dag.py
[2024-12-16T18:15:15.658+0000] {logging_mixin.py:190} INFO - [2024-12-16T18:15:15.656+0000] {dagbag.py:387} ERROR - Failed to import: /opt/airflow/dags/my_dag.py
Traceback (most recent call last):
  File "/home/airflow/.local/lib/python3.12/site-packages/airflow/models/dagbag.py", line 383, in parse
    loader.exec_module(new_module)
  File "<frozen importlib._bootstrap_external>", line 995, in exec_module
  File "<frozen importlib._bootstrap_external>", line 1133, in get_code
  File "<frozen importlib._bootstrap_external>", line 1063, in source_to_code
  File "<frozen importlib._bootstrap>", line 488, in _call_with_frames_removed
  File "/opt/airflow/dags/my_dag.py", line 9
    task_id = 
    ^^^^^^^^^
SyntaxError: expected argument value expression
[2024-12-16T18:15:15.659+0000] {processor.py:927} WARNING - No viable dags retrieved from /opt/airflow/dags/my_dag.py
[2024-12-16T18:15:16.657+0000] {processor.py:208} INFO - Processing /opt/airflow/dags/my_dag.py took 1.044 seconds
[2024-12-16T18:15:17.491+0000] {processor.py:186} INFO - Started process (PID=6760) to work on /opt/airflow/dags/my_dag.py
[2024-12-16T18:15:17.494+0000] {processor.py:914} INFO - Processing file /opt/airflow/dags/my_dag.py for tasks to queue
[2024-12-16T18:15:17.507+0000] {logging_mixin.py:190} INFO - [2024-12-16T18:15:17.506+0000] {dagbag.py:588} INFO - Filling up the DagBag from /opt/airflow/dags/my_dag.py
[2024-12-16T18:15:17.632+0000] {logging_mixin.py:190} INFO - [2024-12-16T18:15:17.626+0000] {dagbag.py:387} ERROR - Failed to import: /opt/airflow/dags/my_dag.py
Traceback (most recent call last):
  File "/home/airflow/.local/lib/python3.12/site-packages/airflow/models/dagbag.py", line 383, in parse
    loader.exec_module(new_module)
  File "<frozen importlib._bootstrap_external>", line 999, in exec_module
  File "<frozen importlib._bootstrap>", line 488, in _call_with_frames_removed
  File "/opt/airflow/dags/my_dag.py", line 8, in <module>
    training_model_A = PythonOperator(
                       ^^^^^^^^^^^^^^^
  File "/home/airflow/.local/lib/python3.12/site-packages/airflow/models/baseoperator.py", line 489, in apply_defaults
    raise AirflowException(f"missing keyword argument {missing_args.pop()!r}")
airflow.exceptions.AirflowException: missing keyword argument 'python_callable'
[2024-12-16T18:15:17.635+0000] {processor.py:927} WARNING - No viable dags retrieved from /opt/airflow/dags/my_dag.py
[2024-12-16T18:15:18.594+0000] {processor.py:208} INFO - Processing /opt/airflow/dags/my_dag.py took 1.138 seconds
[2024-12-16T18:15:49.920+0000] {processor.py:186} INFO - Started process (PID=6800) to work on /opt/airflow/dags/my_dag.py
[2024-12-16T18:15:49.922+0000] {processor.py:914} INFO - Processing file /opt/airflow/dags/my_dag.py for tasks to queue
[2024-12-16T18:15:49.925+0000] {logging_mixin.py:190} INFO - [2024-12-16T18:15:49.925+0000] {dagbag.py:588} INFO - Filling up the DagBag from /opt/airflow/dags/my_dag.py
[2024-12-16T18:15:49.978+0000] {logging_mixin.py:190} INFO - [2024-12-16T18:15:49.959+0000] {dagbag.py:387} ERROR - Failed to import: /opt/airflow/dags/my_dag.py
Traceback (most recent call last):
  File "/home/airflow/.local/lib/python3.12/site-packages/airflow/models/dagbag.py", line 383, in parse
    loader.exec_module(new_module)
  File "<frozen importlib._bootstrap_external>", line 999, in exec_module
  File "<frozen importlib._bootstrap>", line 488, in _call_with_frames_removed
  File "/opt/airflow/dags/my_dag.py", line 8, in <module>
    training_model_A = PythonOperator(
                       ^^^^^^^^^^^^^^^
  File "/home/airflow/.local/lib/python3.12/site-packages/airflow/models/baseoperator.py", line 489, in apply_defaults
    raise AirflowException(f"missing keyword argument {missing_args.pop()!r}")
airflow.exceptions.AirflowException: missing keyword argument 'python_callable'
[2024-12-16T18:15:49.981+0000] {processor.py:927} WARNING - No viable dags retrieved from /opt/airflow/dags/my_dag.py
[2024-12-16T18:15:51.222+0000] {processor.py:208} INFO - Processing /opt/airflow/dags/my_dag.py took 1.322 seconds
[2024-12-16T18:16:10.354+0000] {processor.py:186} INFO - Started process (PID=6848) to work on /opt/airflow/dags/my_dag.py
[2024-12-16T18:16:10.357+0000] {processor.py:914} INFO - Processing file /opt/airflow/dags/my_dag.py for tasks to queue
[2024-12-16T18:16:10.361+0000] {logging_mixin.py:190} INFO - [2024-12-16T18:16:10.360+0000] {dagbag.py:588} INFO - Filling up the DagBag from /opt/airflow/dags/my_dag.py
[2024-12-16T18:16:10.947+0000] {logging_mixin.py:190} INFO - [2024-12-16T18:16:10.918+0000] {dagbag.py:387} ERROR - Failed to import: /opt/airflow/dags/my_dag.py
Traceback (most recent call last):
  File "/home/airflow/.local/lib/python3.12/site-packages/airflow/models/dagbag.py", line 383, in parse
    loader.exec_module(new_module)
  File "<frozen importlib._bootstrap_external>", line 999, in exec_module
  File "<frozen importlib._bootstrap>", line 488, in _call_with_frames_removed
  File "/opt/airflow/dags/my_dag.py", line 8, in <module>
    training_model_A = PythonOperator(
                       ^^^^^^^^^^^^^^^
  File "/home/airflow/.local/lib/python3.12/site-packages/airflow/models/baseoperator.py", line 489, in apply_defaults
    raise AirflowException(f"missing keyword argument {missing_args.pop()!r}")
airflow.exceptions.AirflowException: missing keyword argument 'python_callable'
[2024-12-16T18:16:10.977+0000] {processor.py:927} WARNING - No viable dags retrieved from /opt/airflow/dags/my_dag.py
[2024-12-16T18:16:11.137+0000] {processor.py:208} INFO - Processing /opt/airflow/dags/my_dag.py took 0.802 seconds
[2024-12-16T18:19:21.810+0000] {processor.py:186} INFO - Started process (PID=6905) to work on /opt/airflow/dags/my_dag.py
[2024-12-16T18:19:21.812+0000] {processor.py:914} INFO - Processing file /opt/airflow/dags/my_dag.py for tasks to queue
[2024-12-16T18:19:21.816+0000] {logging_mixin.py:190} INFO - [2024-12-16T18:19:21.816+0000] {dagbag.py:588} INFO - Filling up the DagBag from /opt/airflow/dags/my_dag.py
[2024-12-16T18:19:21.855+0000] {logging_mixin.py:190} INFO - [2024-12-16T18:19:21.852+0000] {dagbag.py:387} ERROR - Failed to import: /opt/airflow/dags/my_dag.py
Traceback (most recent call last):
  File "/home/airflow/.local/lib/python3.12/site-packages/airflow/models/dagbag.py", line 383, in parse
    loader.exec_module(new_module)
  File "<frozen importlib._bootstrap_external>", line 995, in exec_module
  File "<frozen importlib._bootstrap_external>", line 1133, in get_code
  File "<frozen importlib._bootstrap_external>", line 1063, in source_to_code
  File "<frozen importlib._bootstrap>", line 488, in _call_with_frames_removed
  File "/opt/airflow/dags/my_dag.py", line 9
    task_id = "training_model_A"
              
SyntaxError: invalid syntax. Perhaps you forgot a comma?
[2024-12-16T18:19:21.859+0000] {processor.py:927} WARNING - No viable dags retrieved from /opt/airflow/dags/my_dag.py
[2024-12-16T18:19:22.018+0000] {processor.py:208} INFO - Processing /opt/airflow/dags/my_dag.py took 0.225 seconds
[2024-12-16T18:21:29.120+0000] {processor.py:186} INFO - Started process (PID=6988) to work on /opt/airflow/dags/my_dag.py
[2024-12-16T18:21:29.122+0000] {processor.py:914} INFO - Processing file /opt/airflow/dags/my_dag.py for tasks to queue
[2024-12-16T18:21:29.127+0000] {logging_mixin.py:190} INFO - [2024-12-16T18:21:29.126+0000] {dagbag.py:588} INFO - Filling up the DagBag from /opt/airflow/dags/my_dag.py
[2024-12-16T18:21:29.169+0000] {logging_mixin.py:190} INFO - [2024-12-16T18:21:29.167+0000] {dagbag.py:387} ERROR - Failed to import: /opt/airflow/dags/my_dag.py
Traceback (most recent call last):
  File "/home/airflow/.local/lib/python3.12/site-packages/airflow/models/dagbag.py", line 383, in parse
    loader.exec_module(new_module)
  File "<frozen importlib._bootstrap_external>", line 995, in exec_module
  File "<frozen importlib._bootstrap_external>", line 1133, in get_code
  File "<frozen importlib._bootstrap_external>", line 1063, in source_to_code
  File "<frozen importlib._bootstrap>", line 488, in _call_with_frames_removed
  File "/opt/airflow/dags/my_dag.py", line 9
    task_id = "training_model_A"
              ^^^^^
SyntaxError: invalid syntax. Perhaps you forgot a comma?
[2024-12-16T18:21:29.171+0000] {processor.py:927} WARNING - No viable dags retrieved from /opt/airflow/dags/my_dag.py
[2024-12-16T18:21:32.753+0000] {processor.py:208} INFO - Processing /opt/airflow/dags/my_dag.py took 3.646 seconds
[2024-12-16T18:24:29.741+0000] {processor.py:186} INFO - Started process (PID=7064) to work on /opt/airflow/dags/my_dag.py
[2024-12-16T18:24:29.747+0000] {processor.py:914} INFO - Processing file /opt/airflow/dags/my_dag.py for tasks to queue
[2024-12-16T18:24:29.753+0000] {logging_mixin.py:190} INFO - [2024-12-16T18:24:29.751+0000] {dagbag.py:588} INFO - Filling up the DagBag from /opt/airflow/dags/my_dag.py
[2024-12-16T18:24:29.792+0000] {logging_mixin.py:190} INFO - [2024-12-16T18:24:29.790+0000] {dagbag.py:387} ERROR - Failed to import: /opt/airflow/dags/my_dag.py
Traceback (most recent call last):
  File "/home/airflow/.local/lib/python3.12/site-packages/airflow/models/dagbag.py", line 383, in parse
    loader.exec_module(new_module)
  File "<frozen importlib._bootstrap_external>", line 995, in exec_module
  File "<frozen importlib._bootstrap_external>", line 1133, in get_code
  File "<frozen importlib._bootstrap_external>", line 1063, in source_to_code
  File "<frozen importlib._bootstrap>", line 488, in _call_with_frames_removed
  File "/opt/airflow/dags/my_dag.py", line 9
    task_id = "training_model_A"
              ^^^^^
SyntaxError: invalid syntax. Perhaps you forgot a comma?
[2024-12-16T18:24:29.796+0000] {processor.py:927} WARNING - No viable dags retrieved from /opt/airflow/dags/my_dag.py
[2024-12-16T18:24:30.020+0000] {processor.py:208} INFO - Processing /opt/airflow/dags/my_dag.py took 0.291 seconds
[2024-12-16T18:25:25.565+0000] {processor.py:186} INFO - Started process (PID=7111) to work on /opt/airflow/dags/my_dag.py
[2024-12-16T18:25:25.567+0000] {processor.py:914} INFO - Processing file /opt/airflow/dags/my_dag.py for tasks to queue
[2024-12-16T18:25:25.574+0000] {logging_mixin.py:190} INFO - [2024-12-16T18:25:25.572+0000] {dagbag.py:588} INFO - Filling up the DagBag from /opt/airflow/dags/my_dag.py
[2024-12-16T18:25:25.619+0000] {logging_mixin.py:190} INFO - [2024-12-16T18:25:25.617+0000] {dagbag.py:387} ERROR - Failed to import: /opt/airflow/dags/my_dag.py
Traceback (most recent call last):
  File "/home/airflow/.local/lib/python3.12/site-packages/airflow/models/dagbag.py", line 383, in parse
    loader.exec_module(new_module)
  File "<frozen importlib._bootstrap_external>", line 995, in exec_module
  File "<frozen importlib._bootstrap_external>", line 1133, in get_code
  File "<frozen importlib._bootstrap_external>", line 1063, in source_to_code
  File "<frozen importlib._bootstrap>", line 488, in _call_with_frames_removed
  File "/opt/airflow/dags/my_dag.py", line 9
    task_id = "training_model_A"
              ^^^^^
SyntaxError: invalid syntax. Perhaps you forgot a comma?
[2024-12-16T18:25:25.622+0000] {processor.py:927} WARNING - No viable dags retrieved from /opt/airflow/dags/my_dag.py
[2024-12-16T18:25:29.305+0000] {processor.py:208} INFO - Processing /opt/airflow/dags/my_dag.py took 3.777 seconds
[2024-12-16T18:27:49.270+0000] {processor.py:186} INFO - Started process (PID=7175) to work on /opt/airflow/dags/my_dag.py
[2024-12-16T18:27:49.273+0000] {processor.py:914} INFO - Processing file /opt/airflow/dags/my_dag.py for tasks to queue
[2024-12-16T18:27:49.279+0000] {logging_mixin.py:190} INFO - [2024-12-16T18:27:49.278+0000] {dagbag.py:588} INFO - Filling up the DagBag from /opt/airflow/dags/my_dag.py
[2024-12-16T18:27:49.303+0000] {logging_mixin.py:190} INFO - [2024-12-16T18:27:49.301+0000] {dagbag.py:387} ERROR - Failed to import: /opt/airflow/dags/my_dag.py
Traceback (most recent call last):
  File "/home/airflow/.local/lib/python3.12/site-packages/airflow/models/dagbag.py", line 383, in parse
    loader.exec_module(new_module)
  File "<frozen importlib._bootstrap_external>", line 995, in exec_module
  File "<frozen importlib._bootstrap_external>", line 1133, in get_code
  File "<frozen importlib._bootstrap_external>", line 1063, in source_to_code
  File "<frozen importlib._bootstrap>", line 488, in _call_with_frames_removed
  File "/opt/airflow/dags/my_dag.py", line 9
    task_id = "training_model_A"
              ^^^^^
SyntaxError: invalid syntax. Perhaps you forgot a comma?
[2024-12-16T18:27:49.305+0000] {processor.py:927} WARNING - No viable dags retrieved from /opt/airflow/dags/my_dag.py
[2024-12-16T18:27:55.041+0000] {processor.py:208} INFO - Processing /opt/airflow/dags/my_dag.py took 5.786 seconds
[2024-12-16T18:28:26.061+0000] {processor.py:186} INFO - Started process (PID=7244) to work on /opt/airflow/dags/my_dag.py
[2024-12-16T18:28:26.064+0000] {processor.py:914} INFO - Processing file /opt/airflow/dags/my_dag.py for tasks to queue
[2024-12-16T18:28:26.069+0000] {logging_mixin.py:190} INFO - [2024-12-16T18:28:26.068+0000] {dagbag.py:588} INFO - Filling up the DagBag from /opt/airflow/dags/my_dag.py
[2024-12-16T18:28:26.109+0000] {logging_mixin.py:190} INFO - [2024-12-16T18:28:26.107+0000] {dagbag.py:387} ERROR - Failed to import: /opt/airflow/dags/my_dag.py
Traceback (most recent call last):
  File "/home/airflow/.local/lib/python3.12/site-packages/airflow/models/dagbag.py", line 383, in parse
    loader.exec_module(new_module)
  File "<frozen importlib._bootstrap_external>", line 995, in exec_module
  File "<frozen importlib._bootstrap_external>", line 1133, in get_code
  File "<frozen importlib._bootstrap_external>", line 1063, in source_to_code
  File "<frozen importlib._bootstrap>", line 488, in _call_with_frames_removed
  File "/opt/airflow/dags/my_dag.py", line 9
    task_id = "training_model_A"
              ^^^^^
SyntaxError: invalid syntax. Perhaps you forgot a comma?
[2024-12-16T18:28:26.110+0000] {processor.py:927} WARNING - No viable dags retrieved from /opt/airflow/dags/my_dag.py
[2024-12-16T18:28:26.580+0000] {processor.py:208} INFO - Processing /opt/airflow/dags/my_dag.py took 0.532 seconds
[2024-12-16T18:29:03.162+0000] {processor.py:186} INFO - Started process (PID=7303) to work on /opt/airflow/dags/my_dag.py
[2024-12-16T18:29:03.179+0000] {processor.py:914} INFO - Processing file /opt/airflow/dags/my_dag.py for tasks to queue
[2024-12-16T18:29:03.197+0000] {logging_mixin.py:190} INFO - [2024-12-16T18:29:03.196+0000] {dagbag.py:588} INFO - Filling up the DagBag from /opt/airflow/dags/my_dag.py
[2024-12-16T18:29:03.348+0000] {logging_mixin.py:190} INFO - [2024-12-16T18:29:03.346+0000] {dagbag.py:387} ERROR - Failed to import: /opt/airflow/dags/my_dag.py
Traceback (most recent call last):
  File "/home/airflow/.local/lib/python3.12/site-packages/airflow/models/dagbag.py", line 383, in parse
    loader.exec_module(new_module)
  File "<frozen importlib._bootstrap_external>", line 995, in exec_module
  File "<frozen importlib._bootstrap_external>", line 1133, in get_code
  File "<frozen importlib._bootstrap_external>", line 1063, in source_to_code
  File "<frozen importlib._bootstrap>", line 488, in _call_with_frames_removed
  File "/opt/airflow/dags/my_dag.py", line 9
    task_id = "training_model_A"
              ^^^^^
SyntaxError: invalid syntax. Perhaps you forgot a comma?
[2024-12-16T18:29:03.350+0000] {processor.py:927} WARNING - No viable dags retrieved from /opt/airflow/dags/my_dag.py
[2024-12-16T18:29:03.808+0000] {processor.py:208} INFO - Processing /opt/airflow/dags/my_dag.py took 0.696 seconds
[2024-12-16T18:29:09.189+0000] {processor.py:186} INFO - Started process (PID=7316) to work on /opt/airflow/dags/my_dag.py
[2024-12-16T18:29:09.191+0000] {processor.py:914} INFO - Processing file /opt/airflow/dags/my_dag.py for tasks to queue
[2024-12-16T18:29:09.198+0000] {logging_mixin.py:190} INFO - [2024-12-16T18:29:09.197+0000] {dagbag.py:588} INFO - Filling up the DagBag from /opt/airflow/dags/my_dag.py
[2024-12-16T18:29:09.228+0000] {logging_mixin.py:190} INFO - [2024-12-16T18:29:09.226+0000] {dagbag.py:387} ERROR - Failed to import: /opt/airflow/dags/my_dag.py
Traceback (most recent call last):
  File "/home/airflow/.local/lib/python3.12/site-packages/airflow/models/dagbag.py", line 383, in parse
    loader.exec_module(new_module)
  File "<frozen importlib._bootstrap_external>", line 995, in exec_module
  File "<frozen importlib._bootstrap_external>", line 1133, in get_code
  File "<frozen importlib._bootstrap_external>", line 1063, in source_to_code
  File "<frozen importlib._bootstrap>", line 488, in _call_with_frames_removed
  File "/opt/airflow/dags/my_dag.py", line 9
    task_id = "training_model_A"
              ^^^^^
SyntaxError: invalid syntax. Perhaps you forgot a comma?
[2024-12-16T18:29:09.230+0000] {processor.py:927} WARNING - No viable dags retrieved from /opt/airflow/dags/my_dag.py
[2024-12-16T18:29:10.504+0000] {processor.py:208} INFO - Processing /opt/airflow/dags/my_dag.py took 1.329 seconds
[2024-12-16T18:30:31.730+0000] {processor.py:186} INFO - Started process (PID=7373) to work on /opt/airflow/dags/my_dag.py
[2024-12-16T18:30:31.731+0000] {processor.py:914} INFO - Processing file /opt/airflow/dags/my_dag.py for tasks to queue
[2024-12-16T18:30:31.736+0000] {logging_mixin.py:190} INFO - [2024-12-16T18:30:31.736+0000] {dagbag.py:588} INFO - Filling up the DagBag from /opt/airflow/dags/my_dag.py
[2024-12-16T18:30:31.766+0000] {logging_mixin.py:190} INFO - [2024-12-16T18:30:31.764+0000] {dagbag.py:387} ERROR - Failed to import: /opt/airflow/dags/my_dag.py
Traceback (most recent call last):
  File "/home/airflow/.local/lib/python3.12/site-packages/airflow/models/dagbag.py", line 383, in parse
    loader.exec_module(new_module)
  File "<frozen importlib._bootstrap_external>", line 995, in exec_module
  File "<frozen importlib._bootstrap_external>", line 1133, in get_code
  File "<frozen importlib._bootstrap_external>", line 1063, in source_to_code
  File "<frozen importlib._bootstrap>", line 488, in _call_with_frames_removed
  File "/opt/airflow/dags/my_dag.py", line 9
    task_id = "training_model_A"
              ^^^^^
SyntaxError: invalid syntax. Perhaps you forgot a comma?
[2024-12-16T18:30:31.768+0000] {processor.py:927} WARNING - No viable dags retrieved from /opt/airflow/dags/my_dag.py
[2024-12-16T18:30:32.583+0000] {processor.py:208} INFO - Processing /opt/airflow/dags/my_dag.py took 0.868 seconds
[2024-12-16T18:31:05.272+0000] {processor.py:186} INFO - Started process (PID=7435) to work on /opt/airflow/dags/my_dag.py
[2024-12-16T18:31:05.275+0000] {processor.py:914} INFO - Processing file /opt/airflow/dags/my_dag.py for tasks to queue
[2024-12-16T18:31:05.281+0000] {logging_mixin.py:190} INFO - [2024-12-16T18:31:05.280+0000] {dagbag.py:588} INFO - Filling up the DagBag from /opt/airflow/dags/my_dag.py
[2024-12-16T18:31:05.314+0000] {logging_mixin.py:190} INFO - [2024-12-16T18:31:05.312+0000] {dagbag.py:387} ERROR - Failed to import: /opt/airflow/dags/my_dag.py
Traceback (most recent call last):
  File "/home/airflow/.local/lib/python3.12/site-packages/airflow/models/dagbag.py", line 383, in parse
    loader.exec_module(new_module)
  File "<frozen importlib._bootstrap_external>", line 995, in exec_module
  File "<frozen importlib._bootstrap_external>", line 1133, in get_code
  File "<frozen importlib._bootstrap_external>", line 1063, in source_to_code
  File "<frozen importlib._bootstrap>", line 488, in _call_with_frames_removed
  File "/opt/airflow/dags/my_dag.py", line 9
    task_id = "training_model_A"
              ^^^^^
SyntaxError: invalid syntax. Perhaps you forgot a comma?
[2024-12-16T18:31:05.316+0000] {processor.py:927} WARNING - No viable dags retrieved from /opt/airflow/dags/my_dag.py
[2024-12-16T18:31:06.045+0000] {processor.py:208} INFO - Processing /opt/airflow/dags/my_dag.py took 0.789 seconds
[2024-12-16T18:31:41.472+0000] {processor.py:186} INFO - Started process (PID=7495) to work on /opt/airflow/dags/my_dag.py
[2024-12-16T18:31:41.474+0000] {processor.py:914} INFO - Processing file /opt/airflow/dags/my_dag.py for tasks to queue
[2024-12-16T18:31:41.479+0000] {logging_mixin.py:190} INFO - [2024-12-16T18:31:41.479+0000] {dagbag.py:588} INFO - Filling up the DagBag from /opt/airflow/dags/my_dag.py
[2024-12-16T18:31:41.509+0000] {logging_mixin.py:190} INFO - [2024-12-16T18:31:41.507+0000] {dagbag.py:387} ERROR - Failed to import: /opt/airflow/dags/my_dag.py
Traceback (most recent call last):
  File "/home/airflow/.local/lib/python3.12/site-packages/airflow/models/dagbag.py", line 383, in parse
    loader.exec_module(new_module)
  File "<frozen importlib._bootstrap_external>", line 995, in exec_module
  File "<frozen importlib._bootstrap_external>", line 1133, in get_code
  File "<frozen importlib._bootstrap_external>", line 1063, in source_to_code
  File "<frozen importlib._bootstrap>", line 488, in _call_with_frames_removed
  File "/opt/airflow/dags/my_dag.py", line 9
    task_id = "training_model_A"
              ^^^^^
SyntaxError: invalid syntax. Perhaps you forgot a comma?
[2024-12-16T18:31:41.511+0000] {processor.py:927} WARNING - No viable dags retrieved from /opt/airflow/dags/my_dag.py
[2024-12-16T18:31:42.833+0000] {processor.py:208} INFO - Processing /opt/airflow/dags/my_dag.py took 1.379 seconds
[2024-12-16T18:32:13.659+0000] {processor.py:186} INFO - Started process (PID=7559) to work on /opt/airflow/dags/my_dag.py
[2024-12-16T18:32:13.661+0000] {processor.py:914} INFO - Processing file /opt/airflow/dags/my_dag.py for tasks to queue
[2024-12-16T18:32:13.667+0000] {logging_mixin.py:190} INFO - [2024-12-16T18:32:13.666+0000] {dagbag.py:588} INFO - Filling up the DagBag from /opt/airflow/dags/my_dag.py
[2024-12-16T18:32:13.696+0000] {logging_mixin.py:190} INFO - [2024-12-16T18:32:13.693+0000] {dagbag.py:387} ERROR - Failed to import: /opt/airflow/dags/my_dag.py
Traceback (most recent call last):
  File "/home/airflow/.local/lib/python3.12/site-packages/airflow/models/dagbag.py", line 383, in parse
    loader.exec_module(new_module)
  File "<frozen importlib._bootstrap_external>", line 995, in exec_module
  File "<frozen importlib._bootstrap_external>", line 1133, in get_code
  File "<frozen importlib._bootstrap_external>", line 1063, in source_to_code
  File "<frozen importlib._bootstrap>", line 488, in _call_with_frames_removed
  File "/opt/airflow/dags/my_dag.py", line 9
    task_id = "training_model_A"
              ^^^^^
SyntaxError: invalid syntax. Perhaps you forgot a comma?
[2024-12-16T18:32:13.698+0000] {processor.py:927} WARNING - No viable dags retrieved from /opt/airflow/dags/my_dag.py
[2024-12-16T18:32:13.869+0000] {processor.py:208} INFO - Processing /opt/airflow/dags/my_dag.py took 0.228 seconds
[2024-12-16T18:32:44.173+0000] {processor.py:186} INFO - Started process (PID=7623) to work on /opt/airflow/dags/my_dag.py
[2024-12-16T18:32:44.175+0000] {processor.py:914} INFO - Processing file /opt/airflow/dags/my_dag.py for tasks to queue
[2024-12-16T18:32:44.182+0000] {logging_mixin.py:190} INFO - [2024-12-16T18:32:44.181+0000] {dagbag.py:588} INFO - Filling up the DagBag from /opt/airflow/dags/my_dag.py
[2024-12-16T18:32:44.224+0000] {logging_mixin.py:190} INFO - [2024-12-16T18:32:44.221+0000] {dagbag.py:387} ERROR - Failed to import: /opt/airflow/dags/my_dag.py
Traceback (most recent call last):
  File "/home/airflow/.local/lib/python3.12/site-packages/airflow/models/dagbag.py", line 383, in parse
    loader.exec_module(new_module)
  File "<frozen importlib._bootstrap_external>", line 995, in exec_module
  File "<frozen importlib._bootstrap_external>", line 1133, in get_code
  File "<frozen importlib._bootstrap_external>", line 1063, in source_to_code
  File "<frozen importlib._bootstrap>", line 488, in _call_with_frames_removed
  File "/opt/airflow/dags/my_dag.py", line 9
    task_id = "training_model_A"
              ^^^^^
SyntaxError: invalid syntax. Perhaps you forgot a comma?
[2024-12-16T18:32:44.226+0000] {processor.py:927} WARNING - No viable dags retrieved from /opt/airflow/dags/my_dag.py
[2024-12-16T18:32:45.234+0000] {processor.py:208} INFO - Processing /opt/airflow/dags/my_dag.py took 1.079 seconds
[2024-12-16T18:33:25.028+0000] {processor.py:186} INFO - Started process (PID=7693) to work on /opt/airflow/dags/my_dag.py
[2024-12-16T18:33:25.456+0000] {processor.py:914} INFO - Processing file /opt/airflow/dags/my_dag.py for tasks to queue
[2024-12-16T18:33:25.462+0000] {logging_mixin.py:190} INFO - [2024-12-16T18:33:25.461+0000] {dagbag.py:588} INFO - Filling up the DagBag from /opt/airflow/dags/my_dag.py
[2024-12-16T18:33:25.515+0000] {logging_mixin.py:190} INFO - [2024-12-16T18:33:25.511+0000] {dagbag.py:387} ERROR - Failed to import: /opt/airflow/dags/my_dag.py
Traceback (most recent call last):
  File "/home/airflow/.local/lib/python3.12/site-packages/airflow/models/dagbag.py", line 383, in parse
    loader.exec_module(new_module)
  File "<frozen importlib._bootstrap_external>", line 995, in exec_module
  File "<frozen importlib._bootstrap_external>", line 1133, in get_code
  File "<frozen importlib._bootstrap_external>", line 1063, in source_to_code
  File "<frozen importlib._bootstrap>", line 488, in _call_with_frames_removed
  File "/opt/airflow/dags/my_dag.py", line 9
    task_id = "training_model_A"
              ^^^^^
SyntaxError: invalid syntax. Perhaps you forgot a comma?
[2024-12-16T18:33:25.518+0000] {processor.py:927} WARNING - No viable dags retrieved from /opt/airflow/dags/my_dag.py
[2024-12-16T18:33:27.539+0000] {processor.py:208} INFO - Processing /opt/airflow/dags/my_dag.py took 2.528 seconds
[2024-12-16T18:33:57.918+0000] {processor.py:186} INFO - Started process (PID=7747) to work on /opt/airflow/dags/my_dag.py
[2024-12-16T18:33:57.920+0000] {processor.py:914} INFO - Processing file /opt/airflow/dags/my_dag.py for tasks to queue
[2024-12-16T18:33:57.933+0000] {logging_mixin.py:190} INFO - [2024-12-16T18:33:57.927+0000] {dagbag.py:588} INFO - Filling up the DagBag from /opt/airflow/dags/my_dag.py
[2024-12-16T18:33:57.976+0000] {logging_mixin.py:190} INFO - [2024-12-16T18:33:57.974+0000] {dagbag.py:387} ERROR - Failed to import: /opt/airflow/dags/my_dag.py
Traceback (most recent call last):
  File "/home/airflow/.local/lib/python3.12/site-packages/airflow/models/dagbag.py", line 383, in parse
    loader.exec_module(new_module)
  File "<frozen importlib._bootstrap_external>", line 995, in exec_module
  File "<frozen importlib._bootstrap_external>", line 1133, in get_code
  File "<frozen importlib._bootstrap_external>", line 1063, in source_to_code
  File "<frozen importlib._bootstrap>", line 488, in _call_with_frames_removed
  File "/opt/airflow/dags/my_dag.py", line 9
    task_id = "training_model_A"
              ^^^^^
SyntaxError: invalid syntax. Perhaps you forgot a comma?
[2024-12-16T18:33:57.978+0000] {processor.py:927} WARNING - No viable dags retrieved from /opt/airflow/dags/my_dag.py
[2024-12-16T18:33:58.285+0000] {processor.py:208} INFO - Processing /opt/airflow/dags/my_dag.py took 0.390 seconds
[2024-12-16T18:34:35.760+0000] {processor.py:186} INFO - Started process (PID=7792) to work on /opt/airflow/dags/my_dag.py
[2024-12-16T18:34:35.762+0000] {processor.py:914} INFO - Processing file /opt/airflow/dags/my_dag.py for tasks to queue
[2024-12-16T18:34:35.767+0000] {logging_mixin.py:190} INFO - [2024-12-16T18:34:35.766+0000] {dagbag.py:588} INFO - Filling up the DagBag from /opt/airflow/dags/my_dag.py
[2024-12-16T18:34:35.793+0000] {logging_mixin.py:190} INFO - [2024-12-16T18:34:35.791+0000] {dagbag.py:387} ERROR - Failed to import: /opt/airflow/dags/my_dag.py
Traceback (most recent call last):
  File "/home/airflow/.local/lib/python3.12/site-packages/airflow/models/dagbag.py", line 383, in parse
    loader.exec_module(new_module)
  File "<frozen importlib._bootstrap_external>", line 995, in exec_module
  File "<frozen importlib._bootstrap_external>", line 1133, in get_code
  File "<frozen importlib._bootstrap_external>", line 1063, in source_to_code
  File "<frozen importlib._bootstrap>", line 488, in _call_with_frames_removed
  File "/opt/airflow/dags/my_dag.py", line 9
    task_id = "training_model_A"
              ^^^^^
SyntaxError: invalid syntax. Perhaps you forgot a comma?
[2024-12-16T18:34:35.795+0000] {processor.py:927} WARNING - No viable dags retrieved from /opt/airflow/dags/my_dag.py
[2024-12-16T18:34:35.976+0000] {processor.py:208} INFO - Processing /opt/airflow/dags/my_dag.py took 0.230 seconds
[2024-12-16T18:35:06.196+0000] {processor.py:186} INFO - Started process (PID=7852) to work on /opt/airflow/dags/my_dag.py
[2024-12-16T18:35:06.198+0000] {processor.py:914} INFO - Processing file /opt/airflow/dags/my_dag.py for tasks to queue
[2024-12-16T18:35:06.204+0000] {logging_mixin.py:190} INFO - [2024-12-16T18:35:06.203+0000] {dagbag.py:588} INFO - Filling up the DagBag from /opt/airflow/dags/my_dag.py
[2024-12-16T18:35:06.231+0000] {logging_mixin.py:190} INFO - [2024-12-16T18:35:06.229+0000] {dagbag.py:387} ERROR - Failed to import: /opt/airflow/dags/my_dag.py
Traceback (most recent call last):
  File "/home/airflow/.local/lib/python3.12/site-packages/airflow/models/dagbag.py", line 383, in parse
    loader.exec_module(new_module)
  File "<frozen importlib._bootstrap_external>", line 995, in exec_module
  File "<frozen importlib._bootstrap_external>", line 1133, in get_code
  File "<frozen importlib._bootstrap_external>", line 1063, in source_to_code
  File "<frozen importlib._bootstrap>", line 488, in _call_with_frames_removed
  File "/opt/airflow/dags/my_dag.py", line 9
    task_id = "training_model_A"
              ^^^^^
SyntaxError: invalid syntax. Perhaps you forgot a comma?
[2024-12-16T18:35:06.233+0000] {processor.py:927} WARNING - No viable dags retrieved from /opt/airflow/dags/my_dag.py
[2024-12-16T18:35:06.420+0000] {processor.py:208} INFO - Processing /opt/airflow/dags/my_dag.py took 0.239 seconds
[2024-12-16T18:35:38.032+0000] {processor.py:186} INFO - Started process (PID=7909) to work on /opt/airflow/dags/my_dag.py
[2024-12-16T18:35:38.034+0000] {processor.py:914} INFO - Processing file /opt/airflow/dags/my_dag.py for tasks to queue
[2024-12-16T18:35:38.041+0000] {logging_mixin.py:190} INFO - [2024-12-16T18:35:38.040+0000] {dagbag.py:588} INFO - Filling up the DagBag from /opt/airflow/dags/my_dag.py
[2024-12-16T18:35:38.074+0000] {logging_mixin.py:190} INFO - [2024-12-16T18:35:38.071+0000] {dagbag.py:387} ERROR - Failed to import: /opt/airflow/dags/my_dag.py
Traceback (most recent call last):
  File "/home/airflow/.local/lib/python3.12/site-packages/airflow/models/dagbag.py", line 383, in parse
    loader.exec_module(new_module)
  File "<frozen importlib._bootstrap_external>", line 995, in exec_module
  File "<frozen importlib._bootstrap_external>", line 1133, in get_code
  File "<frozen importlib._bootstrap_external>", line 1063, in source_to_code
  File "<frozen importlib._bootstrap>", line 488, in _call_with_frames_removed
  File "/opt/airflow/dags/my_dag.py", line 9
    task_id = "training_model_A"
              ^^^^^
SyntaxError: invalid syntax. Perhaps you forgot a comma?
[2024-12-16T18:35:38.075+0000] {processor.py:927} WARNING - No viable dags retrieved from /opt/airflow/dags/my_dag.py
[2024-12-16T18:35:38.375+0000] {processor.py:208} INFO - Processing /opt/airflow/dags/my_dag.py took 0.362 seconds
[2024-12-16T18:36:14.306+0000] {processor.py:186} INFO - Started process (PID=7966) to work on /opt/airflow/dags/my_dag.py
[2024-12-16T18:36:14.308+0000] {processor.py:914} INFO - Processing file /opt/airflow/dags/my_dag.py for tasks to queue
[2024-12-16T18:36:14.313+0000] {logging_mixin.py:190} INFO - [2024-12-16T18:36:14.312+0000] {dagbag.py:588} INFO - Filling up the DagBag from /opt/airflow/dags/my_dag.py
[2024-12-16T18:36:14.648+0000] {logging_mixin.py:190} INFO - [2024-12-16T18:36:14.644+0000] {dagbag.py:387} ERROR - Failed to import: /opt/airflow/dags/my_dag.py
Traceback (most recent call last):
  File "/home/airflow/.local/lib/python3.12/site-packages/airflow/models/dagbag.py", line 383, in parse
    loader.exec_module(new_module)
  File "<frozen importlib._bootstrap_external>", line 995, in exec_module
  File "<frozen importlib._bootstrap_external>", line 1133, in get_code
  File "<frozen importlib._bootstrap_external>", line 1063, in source_to_code
  File "<frozen importlib._bootstrap>", line 488, in _call_with_frames_removed
  File "/opt/airflow/dags/my_dag.py", line 9
    task_id = "training_model_A"
              ^^^^^
SyntaxError: invalid syntax. Perhaps you forgot a comma?
[2024-12-16T18:36:14.650+0000] {processor.py:927} WARNING - No viable dags retrieved from /opt/airflow/dags/my_dag.py
[2024-12-16T18:36:15.119+0000] {processor.py:208} INFO - Processing /opt/airflow/dags/my_dag.py took 0.824 seconds
[2024-12-16T18:36:46.083+0000] {processor.py:186} INFO - Started process (PID=8031) to work on /opt/airflow/dags/my_dag.py
[2024-12-16T18:36:46.085+0000] {processor.py:914} INFO - Processing file /opt/airflow/dags/my_dag.py for tasks to queue
[2024-12-16T18:36:46.089+0000] {logging_mixin.py:190} INFO - [2024-12-16T18:36:46.089+0000] {dagbag.py:588} INFO - Filling up the DagBag from /opt/airflow/dags/my_dag.py
[2024-12-16T18:36:46.127+0000] {logging_mixin.py:190} INFO - [2024-12-16T18:36:46.125+0000] {dagbag.py:387} ERROR - Failed to import: /opt/airflow/dags/my_dag.py
Traceback (most recent call last):
  File "/home/airflow/.local/lib/python3.12/site-packages/airflow/models/dagbag.py", line 383, in parse
    loader.exec_module(new_module)
  File "<frozen importlib._bootstrap_external>", line 995, in exec_module
  File "<frozen importlib._bootstrap_external>", line 1133, in get_code
  File "<frozen importlib._bootstrap_external>", line 1063, in source_to_code
  File "<frozen importlib._bootstrap>", line 488, in _call_with_frames_removed
  File "/opt/airflow/dags/my_dag.py", line 9
    task_id = "training_model_A"
              ^^^^^
SyntaxError: invalid syntax. Perhaps you forgot a comma?
[2024-12-16T18:36:46.128+0000] {processor.py:927} WARNING - No viable dags retrieved from /opt/airflow/dags/my_dag.py
[2024-12-16T18:36:47.538+0000] {processor.py:208} INFO - Processing /opt/airflow/dags/my_dag.py took 1.466 seconds
[2024-12-16T18:37:21.598+0000] {processor.py:186} INFO - Started process (PID=8086) to work on /opt/airflow/dags/my_dag.py
[2024-12-16T18:37:21.600+0000] {processor.py:914} INFO - Processing file /opt/airflow/dags/my_dag.py for tasks to queue
[2024-12-16T18:37:21.604+0000] {logging_mixin.py:190} INFO - [2024-12-16T18:37:21.603+0000] {dagbag.py:588} INFO - Filling up the DagBag from /opt/airflow/dags/my_dag.py
[2024-12-16T18:37:21.629+0000] {logging_mixin.py:190} INFO - [2024-12-16T18:37:21.627+0000] {dagbag.py:387} ERROR - Failed to import: /opt/airflow/dags/my_dag.py
Traceback (most recent call last):
  File "/home/airflow/.local/lib/python3.12/site-packages/airflow/models/dagbag.py", line 383, in parse
    loader.exec_module(new_module)
  File "<frozen importlib._bootstrap_external>", line 995, in exec_module
  File "<frozen importlib._bootstrap_external>", line 1133, in get_code
  File "<frozen importlib._bootstrap_external>", line 1063, in source_to_code
  File "<frozen importlib._bootstrap>", line 488, in _call_with_frames_removed
  File "/opt/airflow/dags/my_dag.py", line 9
    task_id = "training_model_A"
              ^^^^^
SyntaxError: invalid syntax. Perhaps you forgot a comma?
[2024-12-16T18:37:21.630+0000] {processor.py:927} WARNING - No viable dags retrieved from /opt/airflow/dags/my_dag.py
[2024-12-16T18:37:21.867+0000] {processor.py:208} INFO - Processing /opt/airflow/dags/my_dag.py took 0.284 seconds
[2024-12-16T18:38:07.257+0000] {processor.py:186} INFO - Started process (PID=8146) to work on /opt/airflow/dags/my_dag.py
[2024-12-16T18:38:07.259+0000] {processor.py:914} INFO - Processing file /opt/airflow/dags/my_dag.py for tasks to queue
[2024-12-16T18:38:07.264+0000] {logging_mixin.py:190} INFO - [2024-12-16T18:38:07.263+0000] {dagbag.py:588} INFO - Filling up the DagBag from /opt/airflow/dags/my_dag.py
[2024-12-16T18:38:07.290+0000] {logging_mixin.py:190} INFO - [2024-12-16T18:38:07.287+0000] {dagbag.py:387} ERROR - Failed to import: /opt/airflow/dags/my_dag.py
Traceback (most recent call last):
  File "/home/airflow/.local/lib/python3.12/site-packages/airflow/models/dagbag.py", line 383, in parse
    loader.exec_module(new_module)
  File "<frozen importlib._bootstrap_external>", line 995, in exec_module
  File "<frozen importlib._bootstrap_external>", line 1133, in get_code
  File "<frozen importlib._bootstrap_external>", line 1063, in source_to_code
  File "<frozen importlib._bootstrap>", line 488, in _call_with_frames_removed
  File "/opt/airflow/dags/my_dag.py", line 9
    task_id = "training_model_A"
              ^^^^^
SyntaxError: invalid syntax. Perhaps you forgot a comma?
[2024-12-16T18:38:07.291+0000] {processor.py:927} WARNING - No viable dags retrieved from /opt/airflow/dags/my_dag.py
[2024-12-16T18:38:07.655+0000] {processor.py:208} INFO - Processing /opt/airflow/dags/my_dag.py took 0.411 seconds
[2024-12-16T18:38:46.835+0000] {processor.py:186} INFO - Started process (PID=8207) to work on /opt/airflow/dags/my_dag.py
[2024-12-16T18:38:46.838+0000] {processor.py:914} INFO - Processing file /opt/airflow/dags/my_dag.py for tasks to queue
[2024-12-16T18:38:46.845+0000] {logging_mixin.py:190} INFO - [2024-12-16T18:38:46.844+0000] {dagbag.py:588} INFO - Filling up the DagBag from /opt/airflow/dags/my_dag.py
[2024-12-16T18:38:46.872+0000] {logging_mixin.py:190} INFO - [2024-12-16T18:38:46.870+0000] {dagbag.py:387} ERROR - Failed to import: /opt/airflow/dags/my_dag.py
Traceback (most recent call last):
  File "/home/airflow/.local/lib/python3.12/site-packages/airflow/models/dagbag.py", line 383, in parse
    loader.exec_module(new_module)
  File "<frozen importlib._bootstrap_external>", line 995, in exec_module
  File "<frozen importlib._bootstrap_external>", line 1133, in get_code
  File "<frozen importlib._bootstrap_external>", line 1063, in source_to_code
  File "<frozen importlib._bootstrap>", line 488, in _call_with_frames_removed
  File "/opt/airflow/dags/my_dag.py", line 9
    task_id = "training_model_A"
              ^^^^^
SyntaxError: invalid syntax. Perhaps you forgot a comma?
[2024-12-16T18:38:46.873+0000] {processor.py:927} WARNING - No viable dags retrieved from /opt/airflow/dags/my_dag.py
[2024-12-16T18:38:47.904+0000] {processor.py:208} INFO - Processing /opt/airflow/dags/my_dag.py took 1.085 seconds
[2024-12-16T18:39:45.180+0000] {processor.py:186} INFO - Started process (PID=8264) to work on /opt/airflow/dags/my_dag.py
[2024-12-16T18:39:45.182+0000] {processor.py:914} INFO - Processing file /opt/airflow/dags/my_dag.py for tasks to queue
[2024-12-16T18:39:45.188+0000] {logging_mixin.py:190} INFO - [2024-12-16T18:39:45.186+0000] {dagbag.py:588} INFO - Filling up the DagBag from /opt/airflow/dags/my_dag.py
[2024-12-16T18:39:45.214+0000] {logging_mixin.py:190} INFO - [2024-12-16T18:39:45.212+0000] {dagbag.py:387} ERROR - Failed to import: /opt/airflow/dags/my_dag.py
Traceback (most recent call last):
  File "/home/airflow/.local/lib/python3.12/site-packages/airflow/models/dagbag.py", line 383, in parse
    loader.exec_module(new_module)
  File "<frozen importlib._bootstrap_external>", line 995, in exec_module
  File "<frozen importlib._bootstrap_external>", line 1133, in get_code
  File "<frozen importlib._bootstrap_external>", line 1063, in source_to_code
  File "<frozen importlib._bootstrap>", line 488, in _call_with_frames_removed
  File "/opt/airflow/dags/my_dag.py", line 9
    task_id = "training_model_A"
              ^^^^^
SyntaxError: invalid syntax. Perhaps you forgot a comma?
[2024-12-16T18:39:45.216+0000] {processor.py:927} WARNING - No viable dags retrieved from /opt/airflow/dags/my_dag.py
[2024-12-16T18:39:51.488+0000] {processor.py:208} INFO - Processing /opt/airflow/dags/my_dag.py took 6.321 seconds
[2024-12-16T18:41:00.167+0000] {processor.py:186} INFO - Started process (PID=8315) to work on /opt/airflow/dags/my_dag.py
[2024-12-16T18:41:00.169+0000] {processor.py:914} INFO - Processing file /opt/airflow/dags/my_dag.py for tasks to queue
[2024-12-16T18:41:00.175+0000] {logging_mixin.py:190} INFO - [2024-12-16T18:41:00.174+0000] {dagbag.py:588} INFO - Filling up the DagBag from /opt/airflow/dags/my_dag.py
[2024-12-16T18:41:00.205+0000] {logging_mixin.py:190} INFO - [2024-12-16T18:41:00.202+0000] {dagbag.py:387} ERROR - Failed to import: /opt/airflow/dags/my_dag.py
Traceback (most recent call last):
  File "/home/airflow/.local/lib/python3.12/site-packages/airflow/models/dagbag.py", line 383, in parse
    loader.exec_module(new_module)
  File "<frozen importlib._bootstrap_external>", line 995, in exec_module
  File "<frozen importlib._bootstrap_external>", line 1133, in get_code
  File "<frozen importlib._bootstrap_external>", line 1063, in source_to_code
  File "<frozen importlib._bootstrap>", line 488, in _call_with_frames_removed
  File "/opt/airflow/dags/my_dag.py", line 9
    task_id = "training_model_A"
              ^^^^^
SyntaxError: invalid syntax. Perhaps you forgot a comma?
[2024-12-16T18:41:00.207+0000] {processor.py:927} WARNING - No viable dags retrieved from /opt/airflow/dags/my_dag.py
[2024-12-16T18:41:00.623+0000] {processor.py:208} INFO - Processing /opt/airflow/dags/my_dag.py took 0.473 seconds
[2024-12-16T18:41:30.771+0000] {processor.py:186} INFO - Started process (PID=8378) to work on /opt/airflow/dags/my_dag.py
[2024-12-16T18:41:30.774+0000] {processor.py:914} INFO - Processing file /opt/airflow/dags/my_dag.py for tasks to queue
[2024-12-16T18:41:30.805+0000] {logging_mixin.py:190} INFO - [2024-12-16T18:41:30.804+0000] {dagbag.py:588} INFO - Filling up the DagBag from /opt/airflow/dags/my_dag.py
[2024-12-16T18:41:30.978+0000] {logging_mixin.py:190} INFO - [2024-12-16T18:41:30.972+0000] {dagbag.py:387} ERROR - Failed to import: /opt/airflow/dags/my_dag.py
Traceback (most recent call last):
  File "/home/airflow/.local/lib/python3.12/site-packages/airflow/models/dagbag.py", line 383, in parse
    loader.exec_module(new_module)
  File "<frozen importlib._bootstrap_external>", line 995, in exec_module
  File "<frozen importlib._bootstrap_external>", line 1133, in get_code
  File "<frozen importlib._bootstrap_external>", line 1063, in source_to_code
  File "<frozen importlib._bootstrap>", line 488, in _call_with_frames_removed
  File "/opt/airflow/dags/my_dag.py", line 9
    task_id = "training_model_A"
              ^^^^^
SyntaxError: invalid syntax. Perhaps you forgot a comma?
[2024-12-16T18:41:30.985+0000] {processor.py:927} WARNING - No viable dags retrieved from /opt/airflow/dags/my_dag.py
[2024-12-16T18:41:31.223+0000] {processor.py:208} INFO - Processing /opt/airflow/dags/my_dag.py took 0.474 seconds
[2024-12-16T18:42:07.350+0000] {processor.py:186} INFO - Started process (PID=8442) to work on /opt/airflow/dags/my_dag.py
[2024-12-16T18:42:07.352+0000] {processor.py:914} INFO - Processing file /opt/airflow/dags/my_dag.py for tasks to queue
[2024-12-16T18:42:07.357+0000] {logging_mixin.py:190} INFO - [2024-12-16T18:42:07.356+0000] {dagbag.py:588} INFO - Filling up the DagBag from /opt/airflow/dags/my_dag.py
[2024-12-16T18:42:07.387+0000] {logging_mixin.py:190} INFO - [2024-12-16T18:42:07.385+0000] {dagbag.py:387} ERROR - Failed to import: /opt/airflow/dags/my_dag.py
Traceback (most recent call last):
  File "/home/airflow/.local/lib/python3.12/site-packages/airflow/models/dagbag.py", line 383, in parse
    loader.exec_module(new_module)
  File "<frozen importlib._bootstrap_external>", line 995, in exec_module
  File "<frozen importlib._bootstrap_external>", line 1133, in get_code
  File "<frozen importlib._bootstrap_external>", line 1063, in source_to_code
  File "<frozen importlib._bootstrap>", line 488, in _call_with_frames_removed
  File "/opt/airflow/dags/my_dag.py", line 9
    task_id = "training_model_A"
              ^^^^^
SyntaxError: invalid syntax. Perhaps you forgot a comma?
[2024-12-16T18:42:07.389+0000] {processor.py:927} WARNING - No viable dags retrieved from /opt/airflow/dags/my_dag.py
[2024-12-16T18:42:09.909+0000] {processor.py:208} INFO - Processing /opt/airflow/dags/my_dag.py took 2.570 seconds
[2024-12-16T18:42:40.208+0000] {processor.py:186} INFO - Started process (PID=8505) to work on /opt/airflow/dags/my_dag.py
[2024-12-16T18:42:40.210+0000] {processor.py:914} INFO - Processing file /opt/airflow/dags/my_dag.py for tasks to queue
[2024-12-16T18:42:40.216+0000] {logging_mixin.py:190} INFO - [2024-12-16T18:42:40.216+0000] {dagbag.py:588} INFO - Filling up the DagBag from /opt/airflow/dags/my_dag.py
[2024-12-16T18:42:40.248+0000] {logging_mixin.py:190} INFO - [2024-12-16T18:42:40.245+0000] {dagbag.py:387} ERROR - Failed to import: /opt/airflow/dags/my_dag.py
Traceback (most recent call last):
  File "/home/airflow/.local/lib/python3.12/site-packages/airflow/models/dagbag.py", line 383, in parse
    loader.exec_module(new_module)
  File "<frozen importlib._bootstrap_external>", line 995, in exec_module
  File "<frozen importlib._bootstrap_external>", line 1133, in get_code
  File "<frozen importlib._bootstrap_external>", line 1063, in source_to_code
  File "<frozen importlib._bootstrap>", line 488, in _call_with_frames_removed
  File "/opt/airflow/dags/my_dag.py", line 9
    task_id = "training_model_A"
              ^^^^^
SyntaxError: invalid syntax. Perhaps you forgot a comma?
[2024-12-16T18:42:40.250+0000] {processor.py:927} WARNING - No viable dags retrieved from /opt/airflow/dags/my_dag.py
[2024-12-16T18:42:40.465+0000] {processor.py:208} INFO - Processing /opt/airflow/dags/my_dag.py took 0.270 seconds
[2024-12-16T18:43:11.298+0000] {processor.py:186} INFO - Started process (PID=8570) to work on /opt/airflow/dags/my_dag.py
[2024-12-16T18:43:11.300+0000] {processor.py:914} INFO - Processing file /opt/airflow/dags/my_dag.py for tasks to queue
[2024-12-16T18:43:11.305+0000] {logging_mixin.py:190} INFO - [2024-12-16T18:43:11.304+0000] {dagbag.py:588} INFO - Filling up the DagBag from /opt/airflow/dags/my_dag.py
[2024-12-16T18:43:11.334+0000] {logging_mixin.py:190} INFO - [2024-12-16T18:43:11.331+0000] {dagbag.py:387} ERROR - Failed to import: /opt/airflow/dags/my_dag.py
Traceback (most recent call last):
  File "/home/airflow/.local/lib/python3.12/site-packages/airflow/models/dagbag.py", line 383, in parse
    loader.exec_module(new_module)
  File "<frozen importlib._bootstrap_external>", line 995, in exec_module
  File "<frozen importlib._bootstrap_external>", line 1133, in get_code
  File "<frozen importlib._bootstrap_external>", line 1063, in source_to_code
  File "<frozen importlib._bootstrap>", line 488, in _call_with_frames_removed
  File "/opt/airflow/dags/my_dag.py", line 9
    task_id = "training_model_A"
              ^^^^^
SyntaxError: invalid syntax. Perhaps you forgot a comma?
[2024-12-16T18:43:11.335+0000] {processor.py:927} WARNING - No viable dags retrieved from /opt/airflow/dags/my_dag.py
[2024-12-16T18:43:11.672+0000] {processor.py:208} INFO - Processing /opt/airflow/dags/my_dag.py took 0.389 seconds
[2024-12-16T18:43:45.188+0000] {processor.py:186} INFO - Started process (PID=8602) to work on /opt/airflow/dags/my_dag.py
[2024-12-16T18:43:45.190+0000] {processor.py:914} INFO - Processing file /opt/airflow/dags/my_dag.py for tasks to queue
[2024-12-16T18:43:45.194+0000] {logging_mixin.py:190} INFO - [2024-12-16T18:43:45.193+0000] {dagbag.py:588} INFO - Filling up the DagBag from /opt/airflow/dags/my_dag.py
[2024-12-16T18:43:45.218+0000] {logging_mixin.py:190} INFO - [2024-12-16T18:43:45.216+0000] {dagbag.py:387} ERROR - Failed to import: /opt/airflow/dags/my_dag.py
Traceback (most recent call last):
  File "/home/airflow/.local/lib/python3.12/site-packages/airflow/models/dagbag.py", line 383, in parse
    loader.exec_module(new_module)
  File "<frozen importlib._bootstrap_external>", line 995, in exec_module
  File "<frozen importlib._bootstrap_external>", line 1133, in get_code
  File "<frozen importlib._bootstrap_external>", line 1063, in source_to_code
  File "<frozen importlib._bootstrap>", line 488, in _call_with_frames_removed
  File "/opt/airflow/dags/my_dag.py", line 9
    task_id = "training_model_A"
              ^^^^^
SyntaxError: invalid syntax. Perhaps you forgot a comma?
[2024-12-16T18:43:45.219+0000] {processor.py:927} WARNING - No viable dags retrieved from /opt/airflow/dags/my_dag.py
[2024-12-16T18:43:49.649+0000] {processor.py:208} INFO - Processing /opt/airflow/dags/my_dag.py took 4.471 seconds
